Workbook

Sheet VR Template-XRintTest
A1: Time | B1: Coverage | C1: Run 1 | D1: Run 2 | E1: Run 3 | F1: Run 4 | G1: Run 5 | J1: Trigger | K1: Grab | L1: Total | M1: Time
A2: 30 | B2: =AVERAGE(C2:G2) -> 0.86666667 | C2: =8/9 -> 0.88888889 | D2: =8/9 -> 0.88888889 | E2: =7/9 -> 0.77777778 | F2: =8/9 -> 0.88888889 | G2: =8/9 -> 0.88888889 | I2: Run 1 | J2: 1/1 | K2: 8/8 | L2: 9/9 | M2: 36.1
A3: 60 | B3: =AVERAGE(C3:G3) -> 1 | C3: =9/9 -> 1 | D3: =9/9 -> 1 | E3: =9/9 -> 1 | F3: =9/9 -> 1 | G3: =9/9 -> 1 | I3: Run 2 | J3: 1/1 | K3: 8/8 | L3: 9/9 | M3: 35.1
A4: 90 | B4: =AVERAGE(C4:G4) -> 1 | C4: =9/9 -> 1 | D4: =9/9 -> 1 | E4: =9/9 -> 1 | F4: =9/9 -> 1 | G4: =9/9 -> 1 | I4: Run 3 | J4: 1/1 | K4: 8/8 | L4: 9/9 | M4: 39.7
A5: 120 | B5: =AVERAGE(C5:G5) -> 1 | C5: =9/9 -> 1 | D5: =9/9 -> 1 | E5: =9/9 -> 1 | F5: =9/9 -> 1 | G5: =9/9 -> 1 | I5: Run 4 | J5: 1/1 | K5: 8/8 | L5: 9/9 | M5: 34.6
A6: 150 | B6: =AVERAGE(C6:G6) -> 1 | C6: =9/9 -> 1 | D6: =9/9 -> 1 | E6: =9/9 -> 1 | F6: =9/9 -> 1 | G6: =9/9 -> 1 | I6: Run 5 | J6: 1/1 | K6: 8/8 | L6: 9/9 | M6: 33.7
A7: 180 | B7: =AVERAGE(C7:G7) -> 1 | C7: =9/9 -> 1 | D7: =9/9 -> 1 | E7: =9/9 -> 1 | F7: =9/9 -> 1 | G7: =9/9 -> 1 | I7: Average | J7: 1/1 | K7: 8/8 | L7: 9/9 | M7: =AVERAGE(M2:M6) -> 35.84
A8: 210 | B8: =AVERAGE(C8:G8) -> 1 | C8: =9/9 -> 1 | D8: =9/9 -> 1 | E8: =9/9 -> 1 | F8: =9/9 -> 1 | G8: =9/9 -> 1
A9: 240 | B9: =AVERAGE(C9:G9) -> 1 | C9: =9/9 -> 1 | D9: =9/9 -> 1 | E9: =9/9 -> 1 | F9: =9/9 -> 1 | G9: =9/9 -> 1
A10: 270 | B10: =AVERAGE(C10:G10) -> 1 | C10: =9/9 -> 1 | D10: =9/9 -> 1 | E10: =9/9 -> 1 | F10: =9/9 -> 1 | G10: =9/9 -> 1
A11: 300 | B11: =AVERAGE(C11:G11) -> 1 | C11: =9/9 -> 1 | D11: =9/9 -> 1 | E11: =9/9 -> 1 | F11: =9/9 -> 1 | G11: =9/9 -> 1
A12: 330 | B12: =AVERAGE(C12:G12) -> 1 | C12: =9/9 -> 1 | D12: =9/9 -> 1 | E12: =9/9 -> 1 | F12: =9/9 -> 1 | G12: =9/9 -> 1
A13: 360 | B13: =AVERAGE(C13:G13) -> 1 | C13: =9/9 -> 1 | D13: =9/9 -> 1 | E13: =9/9 -> 1 | F13: =9/9 -> 1 | G13: =9/9 -> 1
A14: 390 | B14: =AVERAGE(C14:G14) -> 1 | C14: =9/9 -> 1 | D14: =9/9 -> 1 | E14: =9/9 -> 1 | F14: =9/9 -> 1 | G14: =9/9 -> 1
A15: 420 | B15: =AVERAGE(C15:G15) -> 1 | C15: =9/9 -> 1 | D15: =9/9 -> 1 | E15: =9/9 -> 1 | F15: =9/9 -> 1 | G15: =9/9 -> 1
A16: 450 | B16: =AVERAGE(C16:G16) -> 1 | C16: =9/9 -> 1 | D16: =9/9 -> 1 | E16: =9/9 -> 1 | F16: =9/9 -> 1 | G16: =9/9 -> 1
A17: 480 | B17: =AVERAGE(C17:G17) -> 1 | C17: =9/9 -> 1 | D17: =9/9 -> 1 | E17: =9/9 -> 1 | F17: =9/9 -> 1 | G17: =9/9 -> 1
A18: 510 | B18: =AVERAGE(C18:G18) -> 1 | C18: =9/9 -> 1 | D18: =9/9 -> 1 | E18: =9/9 -> 1 | F18: =9/9 -> 1 | G18: =9/9 -> 1
A19: 540 | B19: =AVERAGE(C19:G19) -> 1 | C19: =9/9 -> 1 | D19: =9/9 -> 1 | E19: =9/9 -> 1 | F19: =9/9 -> 1 | G19: =9/9 -> 1
... A21: 600 | B21: =AVERAGE(C21:G21) -> 1 | C21: =9/9 -> 1 | D21: =9/9 -> 1 | E21: =9/9 -> 1 | F21: =9/9 -> 1 | G21: =9/9 -> 1

Sheet VR Template-Random
A1: Time | B1: Coverage | C1: Run 1 | D1: Run 2 | E1: Run 3 | F1: Run 4 | G1: Run 5 | H1: Tempt 6 | I1: Tempt 7 | J1: Tempt 8 | K1: Tempt 9 | L1: Tempt 10 | O1: Trigger | P1: Grab | Q1: Total
A2: 30 | B2: =AVERAGE(C2:G2) -> 0.066666667 | C2: =0/9 -> 0 | D2: =0/9 -> 0 | E2: =0/9 -> 0 | F2: =1/9 -> 0.11111111 | G2: =2/9 -> 0.22222222 | H2: =2/9 -> 0.22222222 | I2: =0/9 -> 0 | J2: =1/9 -> 0.11111111 | K2: =2/9 -> 0.22222222 | L2: =2/9 -> 0.22222222 | N2: Number | O2: 1 | P2: 8 | Q2: 9
A3: 60 | B3: =AVERAGE(C3:G3) -> 0.11111111 | C3: =0/9 -> 0 | D3: =0/9 -> 0 | E3: =0/9 -> 0 | F3: =2/9 -> 0.22222222 | G3: =3/9 -> 0.33333333 | H3: =3/9 -> 0.33333333 | I3: =0/9 -> 0 | J3: =2/9 -> 0.22222222 | K3: =3/9 -> 0.33333333 | L3: =2/9 -> 0.22222222 | N3: Run 1 | O3: 0 | P3: 2 | Q3: 2
A4: 90 | B4: =AVERAGE(C4:G4) -> 0.17777778 | C4: =0/9 -> 0 | D4: =2/9 -> 0.22222222 | E4: =1/9 -> 0.11111111 | F4: =2/9 -> 0.22222222 | G4: =3/9 -> 0.33333333 | H4: =4/9 -> 0.44444444 | I4: =0/9 -> 0 | J4: =2/9 -> 0.22222222 | K4: =3/9 -> 0.33333333 | L4: =2/9 -> 0.22222222 | N4: Run 2 | O4: 0 | P4: 4 | Q4: 4
A5: 120 | B5: =AVERAGE(C5:G5) -> 0.24444444 | C5: =1/9 -> 0.11111111 | D5: =4/9 -> 0.44444444 | E5: =1/9 -> 0.11111111 | F5: =2/9 -> 0.22222222 | G5: =3/9 -> 0.33333333 | H5: =4/9 -> 0.44444444 | I5: =0/9 -> 0 | J5: =2/9 -> 0.22222222 | K5: =3/9 -> 0.33333333 | L5: =2/9 -> 0.22222222 | N5: Run 3 | O5: 0 | P5: 4 | Q5: 4
A6: 150 | B6: =AVERAGE(C6:G6) -> 0.24444444 | C6: =1/9 -> 0.11111111 | D6: =4/9 -> 0.44444444 | E6: =1/9 -> 0.11111111 | F6: =2/9 -> 0.22222222 | G6: =3/9 -> 0.33333333 | H6: =4/9 -> 0.44444444 | I6: =0/9 -> 0 | J6: =2/9 -> 0.22222222 | K6: =3/9 -> 0.33333333 | L6: =2/9 -> 0.22222222 | N6: Run 4 | O6: 0 | P6: 5 | Q6: 5
A7: 180 | B7: =AVERAGE(C7:G7) -> 0.26666667 | C7: =2/9 -> 0.22222222 | D7: =4/9 -> 0.44444444 | E7: =1/9 -> 0.11111111 | F7: =2/9 -> 0.22222222 | G7: =3/9 -> 0.33333333 | H7: =4/9 -> 0.44444444 | I7: =0/9 -> 0 | J7: =2/9 -> 0.22222222 | K7: =4/9 -> 0.44444444 | L7: =2/9 -> 0.22222222 | N7: Run 5 | O7: 0 | P7: 3 | Q7: 3
A8: 210 | B8: =AVERAGE(C8:G8) -> 0.26666667 | C8: =2/9 -> 0.22222222 | D8: =4/9 -> 0.44444444 | E8: =1/9 -> 0.11111111 | F8: =2/9 -> 0.22222222 | G8: =3/9 -> 0.33333333 | H8: =4/9 -> 0.44444444 | I8: =1/9 -> 0.11111111 | J8: =2/9 -> 0.22222222 | K8: =6/9 -> 0.66666667 | L8: =3/9 -> 0.33333333 | N8: Run 6 | O8: 0 | P8: 5 | Q8: 5
A9: 240 | B9: =AVERAGE(C9:G9) -> 0.31111111 | C9: =2/9 -> 0.22222222 | D9: =4/9 -> 0.44444444 | E9: =2/9 -> 0.22222222 | F9: =3/9 -> 0.33333333 | G9: =3/9 -> 0.33333333 | H9: =5/9 -> 0.55555556 | I9: =1/9 -> 0.11111111 | J9: =2/9 -> 0.22222222 | K9: =6/9 -> 0.66666667 | L9: =4/9 -> 0.44444444 | N9: Run 7 | O9: 0 | P9: 3 | Q9: 3
A10: 270 | B10: =AVERAGE(C10:G10) -> 0.31111111 | C10: =2/9 -> 0.22222222 | D10: =4/9 -> 0.44444444 | E10: =2/9 -> 0.22222222 | F10: =3/9 -> 0.33333333 | G10: =3/9 -> 0.33333333 | H10: =5/9 -> 0.55555556 | I10: =1/9 -> 0.11111111 | J10: =2/9 -> 0.22222222 | K10: =6/9 -> 0.66666667 | L10: =4/9 -> 0.44444444 | N10: Run 8 | O10: 0 | P10: 6 | Q10: 6
A11: 300 | B11: =AVERAGE(C11:G11) -> 0.33333333 | C11: =2/9 -> 0.22222222 | D11: =4/9 -> 0.44444444 | E11: =3/9 -> 0.33333333 | F11: =3/9 -> 0.33333333 | G11: =3/9 -> 0.33333333 | H11: =5/9 -> 0.55555556 | I11: =1/9 -> 0.11111111 | J11: =2/9 -> 0.22222222 | K11: =6/9 -> 0.66666667 | L11: =4/9 -> 0.44444444 | N11: Run 9 | O11: 0 | P11: 6 | Q11: 6
A12: 330 | B12: =AVERAGE(C12:G12) -> 0.35555556 | C12: =2/9 -> 0.22222222 | D12: =4/9 -> 0.44444444 | E12: =4/9 -> 0.44444444 | F12: =3/9 -> 0.33333333 | G12: =3/9 -> 0.33333333 | H12: =5/9 -> 0.55555556 | I12: =2/9 -> 0.22222222 | J12: =2/9 -> 0.22222222 | K12: =6/9 -> 0.66666667 | L12: =4/9 -> 0.44444444 | N12: Run 10 | O12: 0 | P12: 4 | Q12: 4
A13: 360 | B13: =AVERAGE(C13:G13) -> 0.35555556 | C13: =2/9 -> 0.22222222 | D13: =4/9 -> 0.44444444 | E13: =4/9 -> 0.44444444 | F13: =3/9 -> 0.33333333 | G13: =3/9 -> 0.33333333 | H13: =5/9 -> 0.55555556 | I13: =2/9 -> 0.22222222 | J13: =3/9 -> 0.33333333 | K13: =6/9 -> 0.66666667 | L13: =4/9 -> 0.44444444 | N13: Average | O13: =AVERAGE(O3:O12) -> 0 | P13: =AVERAGE(P3:P12) -> 4.2 | Q13: =AVERAGE(Q3:Q12) -> 4.2
A14: 390 | B14: =AVERAGE(C14:G14) -> 0.35555556 | C14: =2/9 -> 0.22222222 | D14: =4/9 -> 0.44444444 | E14: =4/9 -> 0.44444444 | F14: =3/9 -> 0.33333333 | G14: =3/9 -> 0.33333333 | H14: =5/9 -> 0.55555556 | I14: =2/9 -> 0.22222222 | J14: =3/9 -> 0.33333333 | K14: =6/9 -> 0.66666667 | L14: =4/9 -> 0.44444444 | O14: 0/1 | P14: 4.2/8 | Q14: 4.2/9
A15: 420 | B15: =AVERAGE(C15:G15) -> 0.37777778 | C15: =2/9 -> 0.22222222 | D15: =4/9 -> 0.44444444 | E15: =4/9 -> 0.44444444 | F15: =4/9 -> 0.44444444 | G15: =3/9 -> 0.33333333 | H15: =5/9 -> 0.55555556 | I15: =2/9 -> 0.22222222 | J15: =4/9 -> 0.44444444 | K15: =6/9 -> 0.66666667 | L15: =4/9 -> 0.44444444
A16: 450 | B16: =AVERAGE(C16:G16) -> 0.37777778 | C16: =2/9 -> 0.22222222 | D16: =4/9 -> 0.44444444 | E16: =4/9 -> 0.44444444 | F16: =4/9 -> 0.44444444 | G16: =3/9 -> 0.33333333 | H16: =5/9 -> 0.55555556 | I16: =2/9 -> 0.22222222 | J16: =5/9 -> 0.55555556 | K16: =6/9 -> 0.66666667 | L16: =4/9 -> 0.44444444
A17: 480 | B17: =AVERAGE(C17:G17) -> 0.37777778 | C17: =2/9 -> 0.22222222 | D17: =4/9 -> 0.44444444 | E17: =4/9 -> 0.44444444 | F17: =4/9 -> 0.44444444 | G17: =3/9 -> 0.33333333 | H17: =5/9 -> 0.55555556 | I17: =2/9 -> 0.22222222 | J17: =6/9 -> 0.66666667 | K17: =6/9 -> 0.66666667 | L17: =4/9 -> 0.44444444
A18: 510 | B18: =AVERAGE(C18:G18) -> 0.37777778 | C18: =2/9 -> 0.22222222 | D18: =4/9 -> 0.44444444 | E18: =4/9 -> 0.44444444 | F18: =4/9 -> 0.44444444 | G18: =3/9 -> 0.33333333 | H18: =5/9 -> 0.55555556 | I18: =2/9 -> 0.22222222 | J18: =6/9 -> 0.66666667 | K18: =6/9 -> 0.66666667 | L18: =4/9 -> 0.44444444
A19: 540 | B19: =AVERAGE(C19:G19) -> 0.37777778 | C19: =2/9 -> 0.22222222 | D19: =4/9 -> 0.44444444 | E19: =4/9 -> 0.44444444 | F19: =4/9 -> 0.44444444 | G19: =3/9 -> 0.33333333 | H19: =5/9 -> 0.55555556 | I19: =2/9 -> 0.22222222 | J19: =6/9 -> 0.66666667 | K19: =6/9 -> 0.66666667 | L19: =4/9 -> 0.44444444
A20: 570 | B20: =AVERAGE(C20:G20) -> 0.37777778 | C20: =2/9 -> 0.22222222 | D20: =4/9 -> 0.44444444 | E20: =4/9 -> 0.44444444 | F20: =4/9 -> 0.44444444 | G20: =3/9 -> 0.33333333 | H20: =5/9 -> 0.55555556 | I20: =3/9 -> 0.33333333 | J20: =6/9 -> 0.66666667 | K20: =6/9 -> 0.66666667 | L20: =4/9 -> 0.44444444
A21: 600 | B21: =AVERAGE(C21:G21) -> 0.4 | C21: =2/9 -> 0.22222222 | D21: =4/9 -> 0.44444444 | E21: =4/9 -> 0.44444444 | F21: =5/9 -> 0.55555556 | G21: =3/9 -> 0.33333333 | H21: =5/9 -> 0.55555556 | I21: =3/9 -> 0.33333333 | J21: =6/9 -> 0.66666667 | K21: =6/9 -> 0.66666667 | L21: =4/9 -> 0.44444444

Sheet XRI Assets-XRintTest
A1: Time | B1: Coverage | C1: Run 1 | D1: Run 2 | E1: Run 3 | F1: Run 4 | G1: Run 5 | J1: Trigger | K1: Grab | L1: Total | M1: Time
A2: 30 | B2: =AVERAGE(C2:G2) -> 0.625 | C2: =7/8 -> 0.875 | D2: =4/8 -> 0.5 | E2: =4/8 -> 0.5 | F2: =4/8 -> 0.5 | G2: =6/8 -> 0.75 | I2: Run 1 | J2: 2/2 | K2: 6/6 | L2: 8/8 | M2: 30.2
A3: 60 | B3: =AVERAGE(C3:G3) -> 1 | C3: =8/8 -> 1 | D3: =8/8 -> 1 | E3: =8/8 -> 1 | F3: =8/8 -> 1 | G3: =8/8 -> 1 | I3: Run 2 | J3: 2/2 | K3: 6/6 | L3: 8/8 | M3: 34.5
A4: 90 | B4: =AVERAGE(C4:G4) -> 1 | C4: =8/8 -> 1 | D4: =8/8 -> 1 | E4: =8/8 -> 1 | F4: =8/8 -> 1 | G4: =8/8 -> 1 | I4: Run 3 | J4: 2/2 | K4: 6/6 | L4: 8/8 | M4: 34.4
A5: 120 | B5: =AVERAGE(C5:G5) -> 1 | C5: =8/8 -> 1 | D5: =8/8 -> 1 | E5: =8/8 -> 1 | F5: =8/8 -> 1 | G5: =8/8 -> 1 | I5: Run 4 | J5: 2/2 | K5: 6/6 | L5: 8/8 | M5: 34.5
A6: 150 | B6: =AVERAGE(C6:G6) -> 1 | C6: =8/8 -> 1 | D6: =8/8 -> 1 | E6: =8/8 -> 1 | F6: =8/8 -> 1 | G6: =8/8 -> 1 | I6: Run 5 | J6: 2/2 | K6: 6/6 | L6: 8/8 | M6: 34.6
A7: 180 | B7: =AVERAGE(C7:G7) -> 1 | C7: =8/8 -> 1 | D7: =8/8 -> 1 | E7: =8/8 -> 1 | F7: =8/8 -> 1 | G7: =8/8 -> 1 | I7: Average | J7: 2/2 | K7: 6/6 | L7: 8/8 | M7: =AVERAGE(M2:M6) -> 33.64
A8: 210 | B8: =AVERAGE(C8:G8) -> 1 | C8: =8/8 -> 1 | D8: =8/8 -> 1 | E8: =8/8 -> 1 | F8: =8/8 -> 1 | G8: =8/8 -> 1
A9: 240 | B9: =AVERAGE(C9:G9) -> 1 | C9: =8/8 -> 1 | D9: =8/8 -> 1 | E9: =8/8 -> 1 | F9: =8/8 -> 1 | G9: =8/8 -> 1
A10: 270 | B10: =AVERAGE(C10:G10) -> 1 | C10: =8/8 -> 1 | D10: =8/8 -> 1 | E10: =8/8 -> 1 | F10: =8/8 -> 1 | G10: =8/8 -> 1
A11: 300 | B11: =AVERAGE(C11:G11) -> 1 | C11: =8/8 -> 1 | D11: =8/8 -> 1 | E11: =8/8 -> 1 | F11: =8/8 -> 1 | G11: =8/8 -> 1
A12: 330 | B12: =AVERAGE(C12:G12) -> 1 | C12: =8/8 -> 1 | D12: =8/8 -> 1 | E12: =8/8 -> 1 | F12: =8/8 -> 1 | G12: =8/8 -> 1
A13: 360 | B13: =AVERAGE(C13:G13) -> 1 | C13: =8/8 -> 1 | D13: =8/8 -> 1 | E13: =8/8 -> 1 | F13: =8/8 -> 1 | G13: =8/8 -> 1
A14: 390 | B14: =AVERAGE(C14:G14) -> 1 | C14: =8/8 -> 1 | D14: =8/8 -> 1 | E14: =8/8 -> 1 | F14: =8/8 -> 1 | G14: =8/8 -> 1
A15: 420 | B15: =AVERAGE(C15:G15) -> 1 | C15: =8/8 -> 1 | D15: =8/8 -> 1 | E15: =8/8 -> 1 | F15: =8/8 -> 1 | G15: =8/8 -> 1
A16: 450 | B16: =AVERAGE(C16:G16) -> 1 | C16: =8/8 -> 1 | D16: =8/8 -> 1 | E16: =8/8 -> 1 | F16: =8/8 -> 1 | G16: =8/8 -> 1
A17: 480 | B17: =AVERAGE(C17:G17) -> 1 | C17: =8/8 -> 1 | D17: =8/8 -> 1 | E17: =8/8 -> 1 | F17: =8/8 -> 1 | G17: =8/8 -> 1
A18: 510 | B18: =AVERAGE(C18:G18) -> 1 | C18: =8/8 -> 1 | D18: =8/8 -> 1 | E18: =8/8 -> 1 | F18: =8/8 -> 1 | G18: =8/8 -> 1
A19: 540 | B19: =AVERAGE(C19:G19) -> 1 | C19: =8/8 -> 1 | D19: =8/8 -> 1 | E19: =8/8 -> 1 | F19: =8/8 -> 1 | G19: =8/8 -> 1
... A21: 600 | B21: =AVERAGE(C21:G21) -> 1 | C21: =8/8 -> 1 | D21: =8/8 -> 1 | E21: =8/8 -> 1 | F21: =8/8 -> 1 | G21: =8/8 -> 1

Sheet XRI Assets-Random
A1: Time | B1: Coverage | C1: Run 1 | D1: Run 2 | E1: Run 3 | F1: Run 4 | G1: Run 5 | J1: Trigger | K1: Grab | L1: Total
A2: 30 | B2: =AVERAGE(C2:G2) -> 0.075 | C2: =1/8 -> 0.125 | D2: =1/8 -> 0.125 | E2: =1/8 -> 0.125 | F2: =0/8 -> 0 | G2: =0/8 -> 0 | I2: Run 1 | J2: 0/2 | K2: 2/6 | L2: 2/8
A3: 60 | B3: =AVERAGE(C3:G3) -> 0.075 | C3: =1/8 -> 0.125 | D3: =1/8 -> 0.125 | E3: =1/8 -> 0.125 | F3: =0/8 -> 0 | G3: =0/8 -> 0 | I3: Run 2 | J3: 0/2 | K3: 3/6 | L3: 3/8
A4: 90 | B4: =AVERAGE(C4:G4) -> 0.125 | C4: =1/8 -> 0.125 | D4: =1/8 -> 0.125 | E4: =2/8 -> 0.25 | F4: =1/8 -> 0.125 | G4: =0/8 -> 0 | I4: Run 3 | J4: 0/2 | K4: 2/6 | L4: 2/8
A5: 120 | B5: =AVERAGE(C5:G5) -> 0.15 | C5: =1/8 -> 0.125 | D5: =1/8 -> 0.125 | E5: =2/8 -> 0.25 | F5: =2/8 -> 0.25 | G5: =0/8 -> 0 | I5: Run 4 | J5: 0/2 | K5: 3/6 | L5: 3/8
A6: 150 | B6: =AVERAGE(C6:G6) -> 0.175 | C6: =2/8 -> 0.25 | D6: =1/8 -> 0.125 | E6: =2/8 -> 0.25 | F6: =2/8 -> 0.25 | G6: =0/8 -> 0 | I6: Run 5 | J6: 0/2 | K6: 3/6 | L6: 3/8
A7: 180 | B7: =AVERAGE(C7:G7) -> 0.2 | C7: =2/8 -> 0.25 | D7: =1/8 -> 0.125 | E7: =2/8 -> 0.25 | F7: =3/8 -> 0.375 | G7: =0/8 -> 0 | I7: Average | J7: 0/2 | K7: 2.6/6 | L7: 2.6/8
A8: 210 | B8: =AVERAGE(C8:G8) -> 0.2 | C8: =2/8 -> 0.25 | D8: =1/8 -> 0.125 | E8: =2/8 -> 0.25 | F8: =3/8 -> 0.375 | G8: =0/8 -> 0
A9: 240 | B9: =AVERAGE(C9:G9) -> 0.2 | C9: =2/8 -> 0.25 | D9: =1/8 -> 0.125 | E9: =2/8 -> 0.25 | F9: =3/8 -> 0.375 | G9: =0/8 -> 0
A10: 270 | B10: =AVERAGE(C10:G10) -> 0.25 | C10: =2/8 -> 0.25 | D10: =2/8 -> 0.25 | E10: =2/8 -> 0.25 | F10: =3/8 -> 0.375 | G10: =1/8 -> 0.125
A11: 300 | B11: =AVERAGE(C11:G11) -> 0.325 | C11: =2/8 -> 0.25 | D11: =3/8 -> 0.375 | E11: =2/8 -> 0.25 | F11: =3/8 -> 0.375 | G11: =3/8 -> 0.375
A12: 330 | B12: =AVERAGE(C12:G12) -> 0.325 | C12: =2/8 -> 0.25 | D12: =3/8 -> 0.375 | E12: =2/8 -> 0.25 | F12: =3/8 -> 0.375 | G12: =3/8 -> 0.375
A13: 360 | B13: =AVERAGE(C13:G13) -> 0.325 | C13: =2/8 -> 0.25 | D13: =3/8 -> 0.375 | E13: =2/8 -> 0.25 | F13: =3/8 -> 0.375 | G13: =3/8 -> 0.375
A14: 390 | B14: =AVERAGE(C14:G14) -> 0.325 | C14: =2/8 -> 0.25 | D14: =3/8 -> 0.375 | E14: =2/8 -> 0.25 | F14: =3/8 -> 0.375 | G14: =3/8 -> 0.375
A15: 420 | B15: =AVERAGE(C15:G15) -> 0.325 | C15: =2/8 -> 0.25 | D15: =3/8 -> 0.375 | E15: =2/8 -> 0.25 | F15: =3/8 -> 0.375 | G15: =3/8 -> 0.375
A16: 450 | B16: =AVERAGE(C16:G16) -> 0.325 | C16: =2/8 -> 0.25 | D16: =3/8 -> 0.375 | E16: =2/8 -> 0.25 | F16: =3/8 -> 0.375 | G16: =3/8 -> 0.375
A17: 480 | B17: =AVERAGE(C17:G17) -> 0.325 | C17: =2/8 -> 0.25 | D17: =3/8 -> 0.375 | E17: =2/8 -> 0.25 | F17: =3/8 -> 0.375 | G17: =3/8 -> 0.375
A18: 510 | B18: =AVERAGE(C18:G18) -> 0.325 | C18: =2/8 -> 0.25 | D18: =3/8 -> 0.375 | E18: =2/8 -> 0.25 | F18: =3/8 -> 0.375 | G18: =3/8 -> 0.375
A19: 540 | B19: =AVERAGE(C19:G19) -> 0.325 | C19: =2/8 -> 0.25 | D19: =3/8 -> 0.375 | E19: =2/8 -> 0.25 | F19: =3/8 -> 0.375 | G19: =3/8 -> 0.375
A20: 570 | B20: =AVERAGE(C20:G20) -> 0.325 | C20: =2/8 -> 0.25 | D20: =3/8 -> 0.375 | E20: =2/8 -> 0.25 | F20: =3/8 -> 0.375 | G20: =3/8 -> 0.375
A21: 600 | B21: =AVERAGE(C21:G21) -> 0.325 | C21: =2/8 -> 0.25 | D21: =3/8 -> 0.375 | E21: =2/8 -> 0.25 | F21: =3/8 -> 0.375 | G21: =3/8 -> 0.375

Sheet EscapeProto-XRintTest
A1: Time | B1: Coverage | C1: Run 1 | D1: Run 2 | E1: Run 3 | F1: Run 4 | G1: Run 5 | J1: Trigger | K1: Grab | L1: Total | M1: Time
A2: 30 | B2: =AVERAGE(C2:G2) -> 0.78823529 | C2: =13/17 -> 0.76470588 | D2: =15/17 -> 0.88235294 | E2: =13/17 -> 0.76470588 | F2: =13/17 -> 0.76470588 | G2: =13/17 -> 0.76470588 | I2: Run 1 | J2: 6/6 | K2: 11/11 | L2: 17/17 | M2: 52.4
A3: 60 | B3: =AVERAGE(C3:G3) -> 1 | C3: =17/17 -> 1 | D3: =17/17 -> 1 | E3: =17/17 -> 1 | F3: =17/17 -> 1 | G3: =17/17 -> 1 | I3: Run 2 | J3: 6/6 | K3: 11/11 | L3: 17/17 | M3: 45.4
A4: 90 | B4: =AVERAGE(C4:G4) -> 1 | C4: =17/17 -> 1 | D4: =17/17 -> 1 | E4: =17/17 -> 1 | F4: =17/17 -> 1 | G4: =17/17 -> 1 | I4: Run 3 | J4: 6/6 | K4: 11/11 | L4: 17/17 | M4: 48.8
A5: 120 | B5: =AVERAGE(C5:G5) -> 1 | C5: =17/17 -> 1 | D5: =17/17 -> 1 | E5: =17/17 -> 1 | F5: =17/17 -> 1 | G5: =17/17 -> 1 | I5: Run 4 | J5: 6/6 | K5: 11/11 | L5: 17/17 | M5: 50.4
A6: 150 | B6: =AVERAGE(C6:G6) -> 1 | C6: =17/17 -> 1 | D6: =17/17 -> 1 | E6: =17/17 -> 1 | F6: =17/17 -> 1 | G6: =17/17 -> 1 | I6: Run 5 | J6: 6/6 | K6: 11/11 | L6: 17/17 | M6: 49.5
A7: 180 | B7: =AVERAGE(C7:G7) -> 1 | C7: =17/17 -> 1 | D7: =17/17 -> 1 | E7: =17/17 -> 1 | F7: =17/17 -> 1 | G7: =17/17 -> 1 | I7: Average | J7: 6/6 | K7: 11/11 | L7: 17/17 | M7: =AVERAGE(M2:M6) -> 49.3
A8: 210 | B8: =AVERAGE(C8:G8) -> 1 | C8: =17/17 -> 1 | D8: =17/17 -> 1 | E8: =17/17 -> 1 | F8: =17/17 -> 1 | G8: =17/17 -> 1
A9: 240 | B9: =AVERAGE(C9:G9) -> 1 | C9: =17/17 -> 1 | D9: =17/17 -> 1 | E9: =17/17 -> 1 | F9: =17/17 -> 1 | G9: =17/17 -> 1
A10: 270 | B10: =AVERAGE(C10:G10) -> 1 | C10: =17/17 -> 1 | D10: =17/17 -> 1 | E10: =17/17 -> 1 | F10: =17/17 -> 1 | G10: =17/17 -> 1
A11: 300 | B11: =AVERAGE(C11:G11) -> 1 | C11: =17/17 -> 1 | D11: =17/17 -> 1 | E11: =17/17 -> 1 | F11: =17/17 -> 1 | G11: =17/17 -> 1
A12: 330 | B12: =AVERAGE(C12:G12) -> 1 | C12: =17/17 -> 1 | D12: =17/17 -> 1 | E12: =17/17 -> 1 | F12: =17/17 -> 1 | G12: =17/17 -> 1
A13: 360 | B13: =AVERAGE(C13:G13) -> 1 | C13: =17/17 -> 1 | D13: =17/17 -> 1 | E13: =17/17 -> 1 | F13: =17/17 -> 1 | G13: =17/17 -> 1
A14: 390 | B14: =AVERAGE(C14:G14) -> 1 | C14: =17/17 -> 1 | D14: =17/17 -> 1 | E14: =17/17 -> 1 | F14: =17/17 -> 1 | G14: =17/17 -> 1
A15: 420 | B15: =AVERAGE(C15:G15) -> 1 | C15: =17/17 -> 1 | D15: =17/17 -> 1 | E15: =17/17 -> 1 | F15: =17/17 -> 1 | G15: =17/17 -> 1
A16: 450 | B16: =AVERAGE(C16:G16) -> 1 | C16: =17/17 -> 1 | D16: =17/17 -> 1 | E16: =17/17 -> 1 | F16: =17/17 -> 1 | G16: =17/17 -> 1
A17: 480 | B17: =AVERAGE(C17:G17) -> 1 | C17: =17/17 -> 1 | D17: =17/17 -> 1 | E17: =17/17 -> 1 | F17: =17/17 -> 1 | G17: =17/17 -> 1
A18: 510 | B18: =AVERAGE(C18:G18) -> 1 | C18: =17/17 -> 1 | D18: =17/17 -> 1 | E18: =17/17 -> 1 | F18: =17/17 -> 1 | G18: =17/17 -> 1
A19: 540 | B19: =AVERAGE(C19:G19) -> 1 | C19: =17/17 -> 1 | D19: =17/17 -> 1 | E19: =17/17 -> 1 | F19: =17/17 -> 1 | G19: =17/17 -> 1
... A21: 600 | B21: =AVERAGE(C21:G21) -> 1 | C21: =17/17 -> 1 | D21: =17/17 -> 1 | E21: =17/17 -> 1 | F21: =17/17 -> 1 | G21: =17/17 -> 1

Sheet EscapeProto-Random
A1: Time | B1: Coverage | C1: Run 1 | D1: Run 2 | E1: Run 3 | F1: Run 4 | G1: Run 5 | J1: Trigger | K1: Grab | L1: Total
A2: 30 | B2: =AVERAGE(C2:G2) -> 0.047058824 | C2: =1/17 -> 0.058823529 | D2: =1/17 -> 0.058823529 | E2: =1/17 -> 0.058823529 | F2: =0/17 -> 0 | G2: =1/17 -> 0.058823529 | I2: Run 1 | J2: 0/6 | K2: 6/11 | L2: 6/17
A3: 60 | B3: =AVERAGE(C3:G3) -> 0.058823529 | C3: =1/17 -> 0.058823529 | D3: =1/17 -> 0.058823529 | E3: =1/17 -> 0.058823529 | F3: =0/17 -> 0 | G3: =2/17 -> 0.11764706 | I3: Run 2 | J3: 0/6 | K3: 3/11 | L3: 3/17
A4: 90 | B4: =AVERAGE(C4:G4) -> 0.070588235 | C4: =1/17 -> 0.058823529 | D4: =2/17 -> 0.11764706 | E4: =1/17 -> 0.058823529 | F4: =0/17 -> 0 | G4: =2/17 -> 0.11764706 | I4: Run 3 | J4: 0/6 | K4: 8/11 | L4: 8/17
A5: 120 | B5: =AVERAGE(C5:G5) -> 0.070588235 | C5: =1/17 -> 0.058823529 | D5: =2/17 -> 0.11764706 | E5: =1/17 -> 0.058823529 | F5: =0/17 -> 0 | G5: =2/17 -> 0.11764706 | I5: Run 4 | J5: 0/6 | K5: 4/11 | L5: 4/17
A6: 150 | B6: =AVERAGE(C6:G6) -> 0.094117647 | C6: =2/17 -> 0.11764706 | D6: =2/17 -> 0.11764706 | E6: =2/17 -> 0.11764706 | F6: =0/17 -> 0 | G6: =2/17 -> 0.11764706 | I6: Run 5 | J6: 0/6 | K6: 4/11 | L6: 4/17
A7: 180 | B7: =AVERAGE(C7:G7) -> 0.14117647 | C7: =2/17 -> 0.11764706 | D7: =3/17 -> 0.17647059 | E7: =2/17 -> 0.11764706 | F7: =1/17 -> 0.058823529 | G7: =4/17 -> 0.23529412 | I7: Average | J7: 0/6 | K7: 5/11 | L7: 5/17
A8: 210 | B8: =AVERAGE(C8:G8) -> 0.14117647 | C8: =2/17 -> 0.11764706 | D8: =3/17 -> 0.17647059 | E8: =2/17 -> 0.11764706 | F8: =1/17 -> 0.058823529 | G8: =4/17 -> 0.23529412
A9: 240 | B9: =AVERAGE(C9:G9) -> 0.15294118 | C9: =2/17 -> 0.11764706 | D9: =3/17 -> 0.17647059 | E9: =3/17 -> 0.17647059 | F9: =1/17 -> 0.058823529 | G9: =4/17 -> 0.23529412
A10: 270 | B10: =AVERAGE(C10:G10) -> 0.17647059 | C10: =2/17 -> 0.11764706 | D10: =3/17 -> 0.17647059 | E10: =4/17 -> 0.23529412 | F10: =2/17 -> 0.11764706 | G10: =4/17 -> 0.23529412
A11: 300 | B11: =AVERAGE(C11:G11) -> 0.2 | C11: =4/17 -> 0.23529412 | D11: =3/17 -> 0.17647059 | E11: =4/17 -> 0.23529412 | F11: =2/17 -> 0.11764706 | G11: =4/17 -> 0.23529412
A12: 330 | B12: =AVERAGE(C12:G12) -> 0.21176471 | C12: =4/17 -> 0.23529412 | D12: =3/17 -> 0.17647059 | E12: =5/17 -> 0.29411765 | F12: =2/17 -> 0.11764706 | G12: =4/17 -> 0.23529412
A13: 360 | B13: =AVERAGE(C13:G13) -> 0.21176471 | C13: =4/17 -> 0.23529412 | D13: =3/17 -> 0.17647059 | E13: =5/17 -> 0.29411765 | F13: =2/17 -> 0.11764706 | G13: =4/17 -> 0.23529412
A14: 390 | B14: =AVERAGE(C14:G14) -> 0.21176471 | C14: =4/17 -> 0.23529412 | D14: =3/17 -> 0.17647059 | E14: =5/17 -> 0.29411765 | F14: =2/17 -> 0.11764706 | G14: =4/17 -> 0.23529412
A15: 420 | B15: =AVERAGE(C15:G15) -> 0.23529412 | C15: =4/17 -> 0.23529412 | D15: =3/17 -> 0.17647059 | E15: =7/17 -> 0.41176471 | F15: =2/17 -> 0.11764706 | G15: =4/17 -> 0.23529412
A16: 450 | B16: =AVERAGE(C16:G16) -> 0.23529412 | C16: =4/17 -> 0.23529412 | D16: =3/17 -> 0.17647059 | E16: =7/17 -> 0.41176471 | F16: =2/17 -> 0.11764706 | G16: =4/17 -> 0.23529412
A17: 480 | B17: =AVERAGE(C17:G17) -> 0.25882353 | C17: =5/17 -> 0.29411765 | D17: =3/17 -> 0.17647059 | E17: =7/17 -> 0.41176471 | F17: =3/17 -> 0.17647059 | G17: =4/17 -> 0.23529412
A18: 510 | B18: =AVERAGE(C18:G18) -> 0.28235294 | C18: =5/17 -> 0.29411765 | D18: =3/17 -> 0.17647059 | E18: =8/17 -> 0.47058824 | F18: =4/17 -> 0.23529412 | G18: =4/17 -> 0.23529412
A19: 540 | B19: =AVERAGE(C19:G19) -> 0.29411765 | C19: =6/17 -> 0.35294118 | D19: =3/17 -> 0.17647059 | E19: =8/17 -> 0.47058824 | F19: =4/17 -> 0.23529412 | G19: =4/17 -> 0.23529412
A20: 570 | B20: =AVERAGE(C20:G20) -> 0.29411765 | C20: =6/17 -> 0.35294118 | D20: =3/17 -> 0.17647059 | E20: =8/17 -> 0.47058824 | F20: =4/17 -> 0.23529412 | G20: =4/17 -> 0.23529412
A21: 600 | B21: =AVERAGE(C21:G21) -> 0.29411765 | C21: =6/17 -> 0.35294118 | D21: =3/17 -> 0.17647059 | E21: =8/17 -> 0.47058824 | F21: =4/17 -> 0.23529412 | G21: =4/17 -> 0.23529412

Sheet EscapeRoom-XRintTest
A1: Time | B1: Coverage | C1: Run 1 | D1: Run 2 | E1: Run 3 | F1: Run 4 | G1: Run 5 | J1: Trigger | K1: Grab | L1: Total | M1: Time | N1: Detected Bugs
A2: 30 | B2: =AVERAGE(C2:G2) -> 0.030534351 | C2: =4/131 -> 0.030534351 | D2: =4/131 -> 0.030534351 | E2: =4/131 -> 0.030534351 | F2: =4/131 -> 0.030534351 | G2: =4/131 -> 0.030534351 | I2: Run 1 | J2: 19/19 | K2: 108/112 | L2: 127/131 | M2: 533.9 | N2: 2
A3: 60 | B3: =AVERAGE(C3:G3) -> 0.10076336 | C3: =11/131 -> 0.083969466 | D3: =15/131 -> 0.11450382 | E3: =14/131 -> 0.10687023 | F3: =12/131 -> 0.091603053 | G3: =14/131 -> 0.10687023 | I3: Run 2 | J3: 17/19 | K3: 105/112 | L3: 122/131 | M3: 446.4 | N3: 2
A4: 90 | B4: =AVERAGE(C4:G4) -> 0.16183206 | C4: =17/131 -> 0.12977099 | D4: =23/131 -> 0.17557252 | E4: =23/131 -> 0.17557252 | F4: =22/131 -> 0.16793893 | G4: =21/131 -> 0.16030534 | I4: Run 3 | J4: 18/19 | K4: 106/112 | L4: 124/131 | M4: 422.8 | N4: 2
A5: 120 | B5: =AVERAGE(C5:G5) -> 0.2351145 | C5: =25/131 -> 0.19083969 | D5: =33/131 -> 0.2519084 | E5: =33/131 -> 0.2519084 | F5: =32/131 -> 0.24427481 | G5: =31/131 -> 0.23664122 | I5: Run 4 | J5: 15/19 | K5: 106/112 | L5: 121/131 | M5: 448.5 | N5: 2
A6: 150 | B6: =AVERAGE(C6:G6) -> 0.29618321 | C6: =32/131 -> 0.24427481 | D6: =41/131 -> 0.3129771 | E6: =41/131 -> 0.3129771 | F6: =40/131 -> 0.30534351 | G6: =40/131 -> 0.30534351 | I6: Run 5 | J6: 19/19 | K6: 108/112 | L6: 127/131 | M6: 447 | N6: 2
A7: 180 | B7: =AVERAGE(C7:G7) -> 0.36030534 | C7: =39/131 -> 0.29770992 | D7: =52/131 -> 0.39694656 | E7: =49/131 -> 0.3740458 | F7: =47/131 -> 0.35877863 | G7: =49/131 -> 0.3740458 | I7: Average | J7: 17.6/19 | K7: 106.6/112 | L7: 124.2/131 | M7: =AVERAGE(M2:M6) -> 459.72 | N7: 2
A8: 210 | B8: =AVERAGE(C8:G8) -> 0.41832061 | C8: =45/131 -> 0.34351145 | D8: =58/131 -> 0.44274809 | E8: =59/131 -> 0.45038168 | F8: =54/131 -> 0.41221374 | G8: =58/131 -> 0.44274809
A9: 240 | B9: =AVERAGE(C9:G9) -> 0.48244275 | C9: =52/131 -> 0.39694656 | D9: =69/131 -> 0.52671756 | E9: =67/131 -> 0.51145038 | F9: =63/131 -> 0.48091603 | G9: =65/131 -> 0.49618321
A10: 270 | B10: =AVERAGE(C10:G10) -> 0.55419847 | C10: =61/131 -> 0.46564885 | D10: =80/131 -> 0.61068702 | E10: =77/131 -> 0.58778626 | F10: =73/131 -> 0.55725191 | G10: =72/131 -> 0.54961832
A11: 300 | B11: =AVERAGE(C11:G11) -> 0.62748092 | C11: =67/131 -> 0.51145038 | D11: =87/131 -> 0.66412214 | E11: =91/131 -> 0.69465649 | F11: =82/131 -> 0.6259542 | G11: =84/131 -> 0.64122137
A12: 330 | B12: =AVERAGE(C12:G12) -> 0.70381679 | C12: =84/131 -> 0.64122137 | D12: =93/131 -> 0.70992366 | E12: =96/131 -> 0.73282443 | F12: =92/131 -> 0.70229008 | G12: =96/131 -> 0.73282443
A13: 360 | B13: =AVERAGE(C13:G13) -> 0.76030534 | C13: =96/131 -> 0.73282443 | D13: =102/131 -> 0.77862595 | E13: =104/131 -> 0.79389313 | F13: =95/131 -> 0.72519084 | G13: =101/131 -> 0.77099237
A14: 390 | B14: =AVERAGE(C14:G14) -> 0.82290076 | C14: =100/131 -> 0.76335878 | D14: =110/131 -> 0.83969466 | E14: =114/131 -> 0.87022901 | F14: =105/131 -> 0.80152672 | G14: =110/131 -> 0.83969466
A15: 420 | B15: =AVERAGE(C15:G15) -> 0.89160305 | C15: =108/131 -> 0.82442748 | D15: =119/131 -> 0.90839695 | E15: =123/131 -> 0.9389313 | F15: =114/131 -> 0.87022901 | G15: =120/131 -> 0.91603053
A16: 450 | B16: =AVERAGE(C16:G16) -> 0.93129771 | C16: =116/131 -> 0.88549618 | D16: =122/131 -> 0.93129771 | E16: =124/131 -> 0.94656489 | F16: =121/131 -> 0.92366412 | G16: =127/131 -> 0.96946565
A17: 480 | B17: =AVERAGE(C17:G17) -> 0.95725191 | C17: =123/131 -> 0.9389313 | D17: =122/131 -> 0.93129771 | E17: =124/131 -> 0.94656489 | F17: =17/17 -> 1 | G17: =127/131 -> 0.96946565
A18: 510 | B18: =AVERAGE(C18:G18) -> 0.96183206 | C18: =126/131 -> 0.96183206 | D18: =122/131 -> 0.93129771 | E18: =124/131 -> 0.94656489 | F18: =17/17 -> 1 | G18: =127/131 -> 0.96946565
A19: 540 | B19: =AVERAGE(C19:G19) -> 0.96335878 | C19: =127/131 -> 0.96946565 | D19: =122/131 -> 0.93129771 | E19: =124/131 -> 0.94656489 | F19: =17/17 -> 1 | G19: =127/131 -> 0.96946565
A20: 570 | B20: =AVERAGE(C20:G20) -> 0.96335878 | C20: =127/131 -> 0.96946565 | D20: =122/131 -> 0.93129771 | E20: =124/131 -> 0.94656489 | F20: =17/17 -> 1 | G20: =127/131 -> 0.96946565
A21: 600 | B21: =AVERAGE(C21:G21) -> 0.96335878 | C21: =127/131 -> 0.96946565 | D21: =122/131 -> 0.93129771 | E21: =124/131 -> 0.94656489 | F21: =17/17 -> 1 | G21: =127/131 -> 0.96946565

Sheet EscapeRoom-Random
A1: Time | B1: Coverage | C1: Run 1 | D1: Run 2 | E1: Run 3 | F1: Run 4 | G1: Run 5 | J1: Trigger | K1: Grab | L1: Total
A2: 30 | B2: =AVERAGE(C2:G2) -> 0.0076335878 | C2: =0/131 -> 0 | D2: =3/131 -> 0.022900763 | E2: =1/131 -> 0.0076335878 | F2: =0/131 -> 0 | G2: =1/131 -> 0.0076335878 | I2: Run 1 | J2: 0/19 | K2: 9/112 | L2: 9/131
A3: 60 | B3: =AVERAGE(C3:G3) -> 0.013740458 | C3: =2/131 -> 0.015267176 | D3: =4/131 -> 0.030534351 | E3: =1/131 -> 0.0076335878 | F3: =1/131 -> 0.0076335878 | G3: =1/131 -> 0.0076335878 | I3: Run 2 | J3: 0/19 | K3: 22/112 | L3: 22/131
A4: 90 | B4: =AVERAGE(C4:G4) -> 0.015267176 | C4: =3/131 -> 0.022900763 | D4: =4/131 -> 0.030534351 | E4: =1/131 -> 0.0076335878 | F4: =1/131 -> 0.0076335878 | G4: =1/131 -> 0.0076335878 | I4: Run 3 | J4: 0/19 | K4: 9/112 | L4: 9/131
A5: 120 | B5: =AVERAGE(C5:G5) -> 0.018320611 | C5: =3/131 -> 0.022900763 | D5: =4/131 -> 0.030534351 | E5: =3/131 -> 0.022900763 | F5: =1/131 -> 0.0076335878 | G5: =1/131 -> 0.0076335878 | I5: Run 4 | J5: 0/19 | K5: 8/112 | L5: 8/131
A6: 150 | B6: =AVERAGE(C6:G6) -> 0.022900763 | C6: =4/131 -> 0.030534351 | D6: =6/131 -> 0.045801527 | E6: =3/131 -> 0.022900763 | F6: =1/131 -> 0.0076335878 | G6: =1/131 -> 0.0076335878 | I6: Run 5 | J6: 0/19 | K6: 3/112 | L6: 3/131
A7: 180 | B7: =AVERAGE(C7:G7) -> 0.022900763 | C7: =4/131 -> 0.030534351 | D7: =6/131 -> 0.045801527 | E7: =3/131 -> 0.022900763 | F7: =1/131 -> 0.0076335878 | G7: =1/131 -> 0.0076335878 | I7: Average | J7: 0/19 | K7: 10.2/112 | L7: 10.2/131
A8: 210 | B8: =AVERAGE(C8:G8) -> 0.022900763 | C8: =4/131 -> 0.030534351 | D8: =6/131 -> 0.045801527 | E8: =3/131 -> 0.022900763 | F8: =1/131 -> 0.0076335878 | G8: =1/131 -> 0.0076335878
A9: 240 | B9: =AVERAGE(C9:G9) -> 0.032061069 | C9: =4/131 -> 0.030534351 | D9: =9/131 -> 0.06870229 | E9: =3/131 -> 0.022900763 | F9: =4/131 -> 0.030534351 | G9: =1/131 -> 0.0076335878
A10: 270 | B10: =AVERAGE(C10:G10) -> 0.041221374 | C10: =4/131 -> 0.030534351 | D10: =13/131 -> 0.099236641 | E10: =3/131 -> 0.022900763 | F10: =4/131 -> 0.030534351 | G10: =3/131 -> 0.022900763
A11: 300 | B11: =AVERAGE(C11:G11) -> 0.045801527 | C11: =4/131 -> 0.030534351 | D11: =15/131 -> 0.11450382 | E11: =4/131 -> 0.030534351 | F11: =4/131 -> 0.030534351 | G11: =3/131 -> 0.022900763
A12: 330 | B12: =AVERAGE(C12:G12) -> 0.048854962 | C12: =4/131 -> 0.030534351 | D12: =16/131 -> 0.1221374 | E12: =4/131 -> 0.030534351 | F12: =5/131 -> 0.038167939 | G12: =3/131 -> 0.022900763
A13: 360 | B13: =AVERAGE(C13:G13) -> 0.048854962 | C13: =4/131 -> 0.030534351 | D13: =16/131 -> 0.1221374 | E13: =4/131 -> 0.030534351 | F13: =5/131 -> 0.038167939 | G13: =3/131 -> 0.022900763
A14: 390 | B14: =AVERAGE(C14:G14) -> 0.048854962 | C14: =4/131 -> 0.030534351 | D14: =16/131 -> 0.1221374 | E14: =4/131 -> 0.030534351 | F14: =5/131 -> 0.038167939 | G14: =3/131 -> 0.022900763
A15: 420 | B15: =AVERAGE(C15:G15) -> 0.048854962 | C15: =4/131 -> 0.030534351 | D15: =16/131 -> 0.1221374 | E15: =4/131 -> 0.030534351 | F15: =5/131 -> 0.038167939 | G15: =3/131 -> 0.022900763
A16: 450 | B16: =AVERAGE(C16:G16) -> 0.054961832 | C16: =5/131 -> 0.038167939 | D16: =17/131 -> 0.12977099 | E16: =6/131 -> 0.045801527 | F16: =5/131 -> 0.038167939 | G16: =3/131 -> 0.022900763
A17: 480 | B17: =AVERAGE(C17:G17) -> 0.058015267 | C17: =5/131 -> 0.038167939 | D17: =17/131 -> 0.12977099 | E17: =8/131 -> 0.061068702 | F17: =5/131 -> 0.038167939 | G17: =3/131 -> 0.022900763
A18: 510 | B18: =AVERAGE(C18:G18) -> 0.06259542 | C18: =5/131 -> 0.038167939 | D18: =19/131 -> 0.14503817 | E18: =9/131 -> 0.06870229 | F18: =5/131 -> 0.038167939 | G18: =3/131 -> 0.022900763
A19: 540 | B19: =AVERAGE(C19:G19) -> 0.06870229 | C19: =8/131 -> 0.061068702 | D19: =20/131 -> 0.15267176 | E19: =9/131 -> 0.06870229 | F19: =5/131 -> 0.038167939 | G19: =3/131 -> 0.022900763
A20: 570 | B20: =AVERAGE(C20:G20) -> 0.071755725 | C20: =8/131 -> 0.061068702 | D20: =20/131 -> 0.15267176 | E20: =9/131 -> 0.06870229 | F20: =7/131 -> 0.053435115 | G20: =3/131 -> 0.022900763
A21: 600 | B21: =AVERAGE(C21:G21) -> 0.077862595 | C21: =9/131 -> 0.06870229 | D21: =22/131 -> 0.16793893 | E21: =9/131 -> 0.06870229 | F21: =8/131 -> 0.061068702 | G21: =3/131 -> 0.022900763

Sheet GameJam-XRintTest
A1: Time | B1: Coverage | C1: Run 1 | D1: Run 2 | E1: Run 3 | F1: Run 4 | G1: Run 5 | J1: Trigger | K1: Grab | L1: Total | M1: Time
A2: 30 | B2: =AVERAGE(C2:G2) -> 0.35833333 | C2: =8/24 -> 0.33333333 | D2: =9/24 -> 0.375 | E2: =9/24 -> 0.375 | F2: =8/24 -> 0.33333333 | G2: =9/24 -> 0.375 | I2: Run 1 | J2: 3/3 | K2: 21/21 | L2: 24/24 | M2: 90.6
A3: 60 | B3: =AVERAGE(C3:G3) -> 0.70833333 | C3: =17/24 -> 0.70833333 | D3: =17/24 -> 0.70833333 | E3: =17/24 -> 0.70833333 | F3: =17/24 -> 0.70833333 | G3: =17/24 -> 0.70833333 | I3: Run 2 | J3: 3/3 | K3: 21/21 | L3: 24/24 | M3: 94.6
A4: 90 | B4: =AVERAGE(C4:G4) -> 0.95 | C4: =23/24 -> 0.95833333 | D4: =22/24 -> 0.91666667 | E4: =23/24 -> 0.95833333 | F4: =22/24 -> 0.91666667 | G4: =24/24 -> 1 | I4: Run 3 | J4: 3/3 | K4: 21/21 | L4: 24/24 | M4: 91
A5: 120 | B5: =AVERAGE(C5:G5) -> 1 | C5: =24/24 -> 1 | D5: =24/24 -> 1 | E5: =24/24 -> 1 | F5: =24/24 -> 1 | G5: =24/24 -> 1 | I5: Run 4 | J5: 3/3 | K5: 21/21 | L5: 24/24 | M5: 96.5
A6: 150 | B6: =AVERAGE(C6:G6) -> 1 | C6: =24/24 -> 1 | D6: =24/24 -> 1 | E6: =24/24 -> 1 | F6: =24/24 -> 1 | G6: =24/24 -> 1 | I6: Run 5 | J6: 3/3 | K6: 21/21 | L6: 24/24 | M6: 89.3
A7: 180 | B7: =AVERAGE(C7:G7) -> 1 | C7: =24/24 -> 1 | D7: =24/24 -> 1 | E7: =24/24 -> 1 | F7: =24/24 -> 1 | G7: =24/24 -> 1 | I7: Average | J7: 3/3 | K7: 21/21 | L7: 24/24 | M7: =AVERAGE(M2:M6) -> 92.4
A8: 210 | B8: =AVERAGE(C8:G8) -> 1 | C8: =24/24 -> 1 | D8: =24/24 -> 1 | E8: =24/24 -> 1 | F8: =24/24 -> 1 | G8: =24/24 -> 1
A9: 240 | B9: =AVERAGE(C9:G9) -> 1 | C9: =24/24 -> 1 | D9: =24/24 -> 1 | E9: =24/24 -> 1 | F9: =24/24 -> 1 | G9: =24/24 -> 1
A10: 270 | B10: =AVERAGE(C10:G10) -> 1 | C10: =24/24 -> 1 | D10: =24/24 -> 1 | E10: =24/24 -> 1 | F10: =24/24 -> 1 | G10: =24/24 -> 1
A11: 300 | B11: =AVERAGE(C11:G11) -> 1 | C11: =24/24 -> 1 | D11: =24/24 -> 1 | E11: =24/24 -> 1 | F11: =24/24 -> 1 | G11: =24/24 -> 1
A12: 330 | B12: =AVERAGE(C12:G12) -> 1 | C12: =24/24 -> 1 | D12: =24/24 -> 1 | E12: =24/24 -> 1 | F12: =24/24 -> 1 | G12: =24/24 -> 1
A13: 360 | B13: =AVERAGE(C13:G13) -> 1 | C13: =24/24 -> 1 | D13: =24/24 -> 1 | E13: =24/24 -> 1 | F13: =24/24 -> 1 | G13: =24/24 -> 1
A14: 390 | B14: =AVERAGE(C14:G14) -> 1 | C14: =24/24 -> 1 | D14: =24/24 -> 1 | E14: =24/24 -> 1 | F14: =24/24 -> 1 | G14: =24/24 -> 1
A15: 420 | B15: =AVERAGE(C15:G15) -> 1 | C15: =24/24 -> 1 | D15: =24/24 -> 1 | E15: =24/24 -> 1 | F15: =24/24 -> 1 | G15: =24/24 -> 1
A16: 450 | B16: =AVERAGE(C16:G16) -> 1 | C16: =24/24 -> 1 | D16: =24/24 -> 1 | E16: =24/24 -> 1 | F16: =24/24 -> 1 | G16: =24/24 -> 1
A17: 480 | B17: =AVERAGE(C17:G17) -> 1 | C17: =24/24 -> 1 | D17: =24/24 -> 1 | E17: =24/24 -> 1 | F17: =24/24 -> 1 | G17: =24/24 -> 1
A18: 510 | B18: =AVERAGE(C18:G18) -> 1 | C18: =24/24 -> 1 | D18: =24/24 -> 1 | E18: =24/24 -> 1 | F18: =24/24 -> 1 | G18: =24/24 -> 1
A19: 540 | B19: =AVERAGE(C19:G19) -> 1 | C19: =24/24 -> 1 | D19: =24/24 -> 1 | E19: =24/24 -> 1 | F19: =24/24 -> 1 | G19: =24/24 -> 1
... A21: 600 | B21: =AVERAGE(C21:G21) -> 1 | C21: =24/24 -> 1 | D21: =24/24 -> 1 | E21: =24/24 -> 1 | F21: =24/24 -> 1 | G21: =24/24 -> 1

Sheet GameJam-Random
A1: Time | B1: Coverage | C1: Run 1 | D1: Run 2 | E1: Run 3 | F1: Run 4 | G1: Run 5 | J1: Trigger | K1: Grab | L1: Total
A2: 30 | B2: =AVERAGE(C2:G2) -> 0.033333333 | C2: =0/24 -> 0 | D2: =1/24 -> 0.041666667 | E2: =1/24 -> 0.041666667 | F2: =1/24 -> 0.041666667 | G2: =1/24 -> 0.041666667 | I2: Run 1 | J2: 0/3 | K2: 5/21 | L2: 5/24
A3: 60 | B3: =AVERAGE(C3:G3) -> 0.033333333 | C3: =0/24 -> 0 | D3: =1/24 -> 0.041666667 | E3: =1/24 -> 0.041666667 | F3: =1/24 -> 0.041666667 | G3: =1/24 -> 0.041666667 | I3: Run 2 | J3: 0/3 | K3: 8/21 | L3: 8/24
A4: 90 | B4: =AVERAGE(C4:G4) -> 0.041666667 | C4: =0/24 -> 0 | D4: =1/24 -> 0.041666667 | E4: =2/24 -> 0.083333333 | F4: =1/24 -> 0.041666667 | G4: =1/24 -> 0.041666667 | I4: Run 3 | J4: 0/3 | K4: 6/21 | L4: 6/24
A5: 120 | B5: =AVERAGE(C5:G5) -> 0.05 | C5: =0/24 -> 0 | D5: =2/24 -> 0.083333333 | E5: =2/24 -> 0.083333333 | F5: =1/24 -> 0.041666667 | G5: =1/24 -> 0.041666667 | I5: Run 4 | J5: 0/3 | K5: 8/21 | L5: 8/24
A6: 150 | B6: =AVERAGE(C6:G6) -> 0.091666667 | C6: =2/24 -> 0.083333333 | D6: =3/24 -> 0.125 | E6: =2/24 -> 0.083333333 | F6: =2/24 -> 0.083333333 | G6: =2/24 -> 0.083333333 | I6: Run 5 | J6: 0/3 | K6: 6/21 | L6: 6/24
A7: 180 | B7: =AVERAGE(C7:G7) -> 0.091666667 | C7: =2/24 -> 0.083333333 | D7: =3/24 -> 0.125 | E7: =2/24 -> 0.083333333 | F7: =2/24 -> 0.083333333 | G7: =2/24 -> 0.083333333 | I7: Average | J7: 0/3 | K7: 6.6/21 | L7: 6.6/24
A8: 210 | B8: =AVERAGE(C8:G8) -> 0.1 | C8: =2/24 -> 0.083333333 | D8: =3/24 -> 0.125 | E8: =2/24 -> 0.083333333 | F8: =2/24 -> 0.083333333 | G8: =3/24 -> 0.125
A9: 240 | B9: =AVERAGE(C9:G9) -> 0.1 | C9: =2/24 -> 0.083333333 | D9: =3/24 -> 0.125 | E9: =2/24 -> 0.083333333 | F9: =2/24 -> 0.083333333 | G9: =3/24 -> 0.125
A10: 270 | B10: =AVERAGE(C10:G10) -> 0.1 | C10: =2/24 -> 0.083333333 | D10: =3/24 -> 0.125 | E10: =2/24 -> 0.083333333 | F10: =2/24 -> 0.083333333 | G10: =3/24 -> 0.125
A11: 300 | B11: =AVERAGE(C11:G11) -> 0.11666667 | C11: =2/24 -> 0.083333333 | D11: =4/24 -> 0.16666667 | E11: =3/24 -> 0.125 | F11: =2/24 -> 0.083333333 | G11: =3/24 -> 0.125
A12: 330 | B12: =AVERAGE(C12:G12) -> 0.11666667 | C12: =2/24 -> 0.083333333 | D12: =4/24 -> 0.16666667 | E12: =3/24 -> 0.125 | F12: =2/24 -> 0.083333333 | G12: =3/24 -> 0.125
A13: 360 | B13: =AVERAGE(C13:G13) -> 0.15 | C13: =4/24 -> 0.16666667 | D13: =4/24 -> 0.16666667 | E13: =3/24 -> 0.125 | F13: =4/24 -> 0.16666667 | G13: =3/24 -> 0.125
A14: 390 | B14: =AVERAGE(C14:G14) -> 0.175 | C14: =4/24 -> 0.16666667 | D14: =5/24 -> 0.20833333 | E14: =3/24 -> 0.125 | F14: =5/24 -> 0.20833333 | G14: =4/24 -> 0.16666667
A15: 420 | B15: =AVERAGE(C15:G15) -> 0.18333333 | C15: =4/24 -> 0.16666667 | D15: =5/24 -> 0.20833333 | E15: =3/24 -> 0.125 | F15: =5/24 -> 0.20833333 | G15: =5/24 -> 0.20833333
A16: 450 | B16: =AVERAGE(C16:G16) -> 0.2 | C16: =4/24 -> 0.16666667 | D16: =5/24 -> 0.20833333 | E16: =3/24 -> 0.125 | F16: =6/24 -> 0.25 | G16: =6/24 -> 0.25
A17: 480 | B17: =AVERAGE(C17:G17) -> 0.21666667 | C17: =5/24 -> 0.20833333 | D17: =5/24 -> 0.20833333 | E17: =3/24 -> 0.125 | F17: =7/24 -> 0.29166667 | G17: =6/24 -> 0.25
A18: 510 | B18: =AVERAGE(C18:G18) -> 0.24166667 | C18: =5/24 -> 0.20833333 | D18: =7/24 -> 0.29166667 | E18: =3/24 -> 0.125 | F18: =8/24 -> 0.33333333 | G18: =6/24 -> 0.25
A19: 540 | B19: =AVERAGE(C19:G19) -> 0.24166667 | C19: =5/24 -> 0.20833333 | D19: =7/24 -> 0.29166667 | E19: =3/24 -> 0.125 | F19: =8/24 -> 0.33333333 | G19: =6/24 -> 0.25
A20: 570 | B20: =AVERAGE(C20:G20) -> 0.25 | C20: =5/24 -> 0.20833333 | D20: =8/24 -> 0.33333333 | E20: =3/24 -> 0.125 | F20: =8/24 -> 0.33333333 | G20: =6/24 -> 0.25
A21: 600 | B21: =AVERAGE(C21:G21) -> 0.275 | C21: =5/24 -> 0.20833333 | D21: =8/24 -> 0.33333333 | E21: =6/24 -> 0.25 | F21: =8/24 -> 0.33333333 | G21: =6/24 -> 0.25

Sheet XRI Kit-XRintTest
A1: Time | B1: Coverage | C1: Run 1 | D1: Run 2 | E1: Run 3 | F1: Run 4 | G1: Run 5 | J1: Trigger | K1: Grab | L1: Total | M1: Time
A2: 30 | B2: =AVERAGE(C2:G2) -> 0.18421053 | C2: =7/38 -> 0.18421053 | D2: =7/38 -> 0.18421053 | E2: =7/38 -> 0.18421053 | F2: =7/38 -> 0.18421053 | G2: =7/38 -> 0.18421053 | I2: Run 1 | J2: 10/10 | K2: 27/28 | L2: 37/38 | M2: 136.1
A3: 60 | B3: =AVERAGE(C3:G3) -> 0.47894737 | C3: =18/38 -> 0.47368421 | D3: =18/38 -> 0.47368421 | E3: =19/38 -> 0.5 | F3: =18/38 -> 0.47368421 | G3: =18/38 -> 0.47368421 | I3: Run 2 | J3: 10/10 | K3: 27/28 | L3: 37/38 | M3: 133.1
A4: 90 | B4: =AVERAGE(C4:G4) -> 0.60526316 | C4: =23/38 -> 0.60526316 | D4: =23/38 -> 0.60526316 | E4: =23/38 -> 0.60526316 | F4: =23/38 -> 0.60526316 | G4: =23/38 -> 0.60526316 | I4: Run 3 | J4: 10/10 | K4: 27/28 | L4: 37/38 | M4: 130.5
A5: 120 | B5: =AVERAGE(C5:G5) -> 0.81052632 | C5: =29/38 -> 0.76315789 | D5: =31/38 -> 0.81578947 | E5: =33/38 -> 0.86842105 | F5: =30/38 -> 0.78947368 | G5: =31/38 -> 0.81578947 | I5: Run 4 | J5: 10/10 | K5: 27/28 | L5: 37/38 | M5: 134.4
A6: 150 | B6: =AVERAGE(C6:G6) -> 0.97368421 | C6: =37/38 -> 0.97368421 | D6: =37/38 -> 0.97368421 | E6: =37/38 -> 0.97368421 | F6: =37/38 -> 0.97368421 | G6: =37/38 -> 0.97368421 | I6: Run 5 | J6: 10/10 | K6: 27/28 | L6: 37/38 | M6: 133.7
A7: 180 | B7: =AVERAGE(C7:G7) -> 0.97368421 | C7: =37/38 -> 0.97368421 | D7: =37/38 -> 0.97368421 | E7: =37/38 -> 0.97368421 | F7: =37/38 -> 0.97368421 | G7: =37/38 -> 0.97368421 | I7: Average | J7: 10/10 | K7: 27/28 | L7: 37/38 | M7: =AVERAGE(M2:M6) -> 133.56
A8: 210 | B8: =AVERAGE(C8:G8) -> 0.97368421 | C8: =37/38 -> 0.97368421 | D8: =37/38 -> 0.97368421 | E8: =37/38 -> 0.97368421 | F8: =37/38 -> 0.97368421 | G8: =37/38 -> 0.97368421
A9: 240 | B9: =AVERAGE(C9:G9) -> 0.97368421 | C9: =37/38 -> 0.97368421 | D9: =37/38 -> 0.97368421 | E9: =37/38 -> 0.97368421 | F9: =37/38 -> 0.97368421 | G9: =37/38 -> 0.97368421
A10: 270 | B10: =AVERAGE(C10:G10) -> 0.97368421 | C10: =37/38 -> 0.97368421 | D10: =37/38 -> 0.97368421 | E10: =37/38 -> 0.97368421 | F10: =37/38 -> 0.97368421 | G10: =37/38 -> 0.97368421
A11: 300 | B11: =AVERAGE(C11:G11) -> 0.97368421 | C11: =37/38 -> 0.97368421 | D11: =37/38 -> 0.97368421 | E11: =37/38 -> 0.97368421 | F11: =37/38 -> 0.97368421 | G11: =37/38 -> 0.97368421
A12: 330 | B12: =AVERAGE(C12:G12) -> 0.97368421 | C12: =37/38 -> 0.97368421 | D12: =37/38 -> 0.97368421 | E12: =37/38 -> 0.97368421 | F12: =37/38 -> 0.97368421 | G12: =37/38 -> 0.97368421
A13: 360 | B13: =AVERAGE(C13:G13) -> 0.97368421 | C13: =37/38 -> 0.97368421 | D13: =37/38 -> 0.97368421 | E13: =37/38 -> 0.97368421 | F13: =37/38 -> 0.97368421 | G13: =37/38 -> 0.97368421
A14: 390 | B14: =AVERAGE(C14:G14) -> 0.97368421 | C14: =37/38 -> 0.97368421 | D14: =37/38 -> 0.97368421 | E14: =37/38 -> 0.97368421 | F14: =37/38 -> 0.97368421 | G14: =37/38 -> 0.97368421
A15: 420 | B15: =AVERAGE(C15:G15) -> 0.97368421 | C15: =37/38 -> 0.97368421 | D15: =37/38 -> 0.97368421 | E15: =37/38 -> 0.97368421 | F15: =37/38 -> 0.97368421 | G15: =37/38 -> 0.97368421
A16: 450 | B16: =AVERAGE(C16:G16) -> 0.97368421 | C16: =37/38 -> 0.97368421 | D16: =37/38 -> 0.97368421 | E16: =37/38 -> 0.97368421 | F16: =37/38 -> 0.97368421 | G16: =37/38 -> 0.97368421
A17: 480 | B17: =AVERAGE(C17:G17) -> 0.97368421 | C17: =37/38 -> 0.97368421 | D17: =37/38 -> 0.97368421 | E17: =37/38 -> 0.97368421 | F17: =37/38 -> 0.97368421 | G17: =37/38 -> 0.97368421
A18: 510 | B18: =AVERAGE(C18:G18) -> 0.97368421 | C18: =37/38 -> 0.97368421 | D18: =37/38 -> 0.97368421 | E18: =37/38 -> 0.97368421 | F18: =37/38 -> 0.97368421 | G18: =37/38 -> 0.97368421
A19: 540 | B19: =AVERAGE(C19:G19) -> 0.97368421 | C19: =37/38 -> 0.97368421 | D19: =37/38 -> 0.97368421 | E19: =37/38 -> 0.97368421 | F19: =37/38 -> 0.97368421 | G19: =37/38 -> 0.97368421
... A21: 600 | B21: =AVERAGE(C21:G21) -> 0.97368421 | C21: =37/38 -> 0.97368421 | D21: =37/38 -> 0.97368421 | E21: =37/38 -> 0.97368421 | F21: =37/38 -> 0.97368421 | G21: =37/38 -> 0.97368421

Sheet XRI Kit-Random
A1: Time | B1: Coverage | C1: Run 1 | D1: Run 2 | E1: Run 3 | F1: Run 4 | G1: Run 5 | J1: Trigger | K1: Grab | L1: Total
A2: 30 | B2: =AVERAGE(C2:G2) -> 0 | C2: =0/38 -> 0 | D2: =0/38 -> 0 | E2: =0/38 -> 0 | F2: =0/38 -> 0 | G2: =0/38 -> 0 | I2: Run 1 | J2: 0/10 | K2: 1/28 | L2: 1/38
A3: 60 | B3: =AVERAGE(C3:G3) -> 0 | C3: =0/38 -> 0 | D3: =0/38 -> 0 | E3: =0/38 -> 0 | F3: =0/38 -> 0 | G3: =0/38 -> 0 | I3: Run 2 | J3: 0/10 | K3: 2/28 | L3: 2/38
A4: 90 | B4: =AVERAGE(C4:G4) -> 0 | C4: =0/38 -> 0 | D4: =0/38 -> 0 | E4: =0/38 -> 0 | F4: =0/38 -> 0 | G4: =0/38 -> 0 | I4: Run 3 | J4: 0/10 | K4: 0/28 | L4: 0/38
A5: 120 | B5: =AVERAGE(C5:G5) -> 0.0052631579 | C5: =1/38 -> 0.026315789 | D5: =0/38 -> 0 | E5: =0/38 -> 0 | F5: =0/38 -> 0 | G5: =0/38 -> 0 | I5: Run 4 | J5: 0/10 | K5: 0/28 | L5: 0/38
A6: 150 | B6: =AVERAGE(C6:G6) -> 0.010526316 | C6: =1/38 -> 0.026315789 | D6: =1/38 -> 0.026315789 | E6: =0/38 -> 0 | F6: =0/38 -> 0 | G6: =0/38 -> 0 | I6: Run 5 | J6: 0/10 | K6: 0/28 | L6: 0/38
A7: 180 | B7: =AVERAGE(C7:G7) -> 0.010526316 | C7: =1/38 -> 0.026315789 | D7: =1/38 -> 0.026315789 | E7: =0/38 -> 0 | F7: =0/38 -> 0 | G7: =0/38 -> 0 | I7: Average | J7: 0/10 | K7: 0.6/28 | L7: 0.6/38
A8: 210 | B8: =AVERAGE(C8:G8) -> 0.010526316 | C8: =1/38 -> 0.026315789 | D8: =1/38 -> 0.026315789 | E8: =0/38 -> 0 | F8: =0/38 -> 0 | G8: =0/38 -> 0
A9: 240 | B9: =AVERAGE(C9:G9) -> 0.010526316 | C9: =1/38 -> 0.026315789 | D9: =1/38 -> 0.026315789 | E9: =0/38 -> 0 | F9: =0/38 -> 0 | G9: =0/38 -> 0
A10: 270 | B10: =AVERAGE(C10:G10) -> 0.010526316 | C10: =1/38 -> 0.026315789 | D10: =1/38 -> 0.026315789 | E10: =0/38 -> 0 | F10: =0/38 -> 0 | G10: =0/38 -> 0
A11: 300 | B11: =AVERAGE(C11:G11) -> 0.010526316 | C11: =1/38 -> 0.026315789 | D11: =1/38 -> 0.026315789 | E11: =0/38 -> 0 | F11: =0/38 -> 0 | G11: =0/38 -> 0
A12: 330 | B12: =AVERAGE(C12:G12) -> 0.010526316 | C12: =1/38 -> 0.026315789 | D12: =1/38 -> 0.026315789 | E12: =0/38 -> 0 | F12: =0/38 -> 0 | G12: =0/38 -> 0
A13: 360 | B13: =AVERAGE(C13:G13) -> 0.010526316 | C13: =1/38 -> 0.026315789 | D13: =1/38 -> 0.026315789 | E13: =0/38 -> 0 | F13: =0/38 -> 0 | G13: =0/38 -> 0
A14: 390 | B14: =AVERAGE(C14:G14) -> 0.010526316 | C14: =1/38 -> 0.026315789 | D14: =1/38 -> 0.026315789 | E14: =0/38 -> 0 | F14: =0/38 -> 0 | G14: =0/38 -> 0
A15: 420 | B15: =AVERAGE(C15:G15) -> 0.010526316 | C15: =1/38 -> 0.026315789 | D15: =1/38 -> 0.026315789 | E15: =0/38 -> 0 | F15: =0/38 -> 0 | G15: =0/38 -> 0
A16: 450 | B16: =AVERAGE(C16:G16) -> 0.015789474 | C16: =1/38 -> 0.026315789 | D16: =2/38 -> 0.052631579 | E16: =0/38 -> 0 | F16: =0/38 -> 0 | G16: =0/38 -> 0
A17: 480 | B17: =AVERAGE(C17:G17) -> 0.015789474 | C17: =1/38 -> 0.026315789 | D17: =2/38 -> 0.052631579 | E17: =0/38 -> 0 | F17: =0/38 -> 0 | G17: =0/38 -> 0
A18: 510 | B18: =AVERAGE(C18:G18) -> 0.015789474 | C18: =1/38 -> 0.026315789 | D18: =2/38 -> 0.052631579 | E18: =0/38 -> 0 | F18: =0/38 -> 0 | G18: =0/38 -> 0
A19: 540 | B19: =AVERAGE(C19:G19) -> 0.015789474 | C19: =1/38 -> 0.026315789 | D19: =2/38 -> 0.052631579 | E19: =0/38 -> 0 | F19: =0/38 -> 0 | G19: =0/38 -> 0
A20: 570 | B20: =AVERAGE(C20:G20) -> 0.015789474 | C20: =1/38 -> 0.026315789 | D20: =2/38 -> 0.052631579 | E20: =0/38 -> 0 | F20: =0/38 -> 0 | G20: =0/38 -> 0
A21: 600 | B21: =AVERAGE(C21:G21) -> 0.015789474 | C21: =1/38 -> 0.026315789 | D21: =2/38 -> 0.052631579 | E21: =0/38 -> 0 | F21: =0/38 -> 0 | G21: =0/38 -> 0

Sheet XRI Examples-XRintTest
A1: Time | B1: Coverage | C1: Run 1 | D1: Run 2 | E1: Run 3 | F1: Run 4 | G1: Run 5 | J1: Trigger | K1: Grab | L1: Total | M1: Time
A2: 30 | B2: =AVERAGE(C2:G2) -> 0.15769231 | C2: =8/52 -> 0.15384615 | D2: =8/52 -> 0.15384615 | E2: =8/52 -> 0.15384615 | F2: =9/52 -> 0.17307692 | G2: =8/52 -> 0.15384615 | I2: Run 1 | J2: 8/8 | K2: 44/44 | L2: 52/52 | M2: 233.7
A3: 60 | B3: =AVERAGE(C3:G3) -> 0.28846154 | C3: =15/52 -> 0.28846154 | D3: =15/52 -> 0.28846154 | E3: =15/52 -> 0.28846154 | F3: =15/52 -> 0.28846154 | G3: =15/52 -> 0.28846154 | I3: Run 2 | J3: 8/8 | K3: 44/44 | L3: 52/52 | M3: 232
A4: 90 | B4: =AVERAGE(C4:G4) -> 0.46153846 | C4: =24/52 -> 0.46153846 | D4: =24/52 -> 0.46153846 | E4: =24/52 -> 0.46153846 | F4: =24/52 -> 0.46153846 | G4: =24/52 -> 0.46153846 | I4: Run 3 | J4: 8/8 | K4: 44/44 | L4: 52/52 | M4: 231.4
A5: 120 | B5: =AVERAGE(C5:G5) -> 0.59230769 | C5: =30/52 -> 0.57692308 | D5: =32/52 -> 0.61538462 | E5: =30/52 -> 0.57692308 | F5: =32/52 -> 0.61538462 | G5: =30/52 -> 0.57692308 | I5: Run 4 | J5: 8/8 | K5: 44/44 | L5: 52/52 | M5: 231.4
A6: 150 | B6: =AVERAGE(C6:G6) -> 0.69615385 | C6: =36/52 -> 0.69230769 | D6: =36/52 -> 0.69230769 | E6: =36/52 -> 0.69230769 | F6: =37/52 -> 0.71153846 | G6: =36/52 -> 0.69230769 | I6: Run 5 | J6: 8/8 | K6: 44/44 | L6: 52/52 | M6: 236.6
A7: 180 | B7: =AVERAGE(C7:G7) -> 0.80769231 | C7: =42/52 -> 0.80769231 | D7: =42/52 -> 0.80769231 | E7: =42/52 -> 0.80769231 | F7: =43/52 -> 0.82692308 | G7: =41/52 -> 0.78846154 | I7: Average | J7: 8/8 | K7: 44/44 | L7: 52/52 | M7: =AVERAGE(M2:M6) -> 233.02
A8: 210 | B8: =AVERAGE(C8:G8) -> 0.94230769 | C8: =49/52 -> 0.94230769 | D8: =49/52 -> 0.94230769 | E8: =49/52 -> 0.94230769 | F8: =49/52 -> 0.94230769 | G8: =49/52 -> 0.94230769
A9: 240 | B9: =AVERAGE(C9:G9) -> 1 | C9: =52/52 -> 1 | D9: =52/52 -> 1 | E9: =52/52 -> 1 | F9: =52/52 -> 1 | G9: =52/52 -> 1
A10: 270 | B10: =AVERAGE(C10:G10) -> 1 | C10: =52/52 -> 1 | D10: =52/52 -> 1 | E10: =52/52 -> 1 | F10: =52/52 -> 1 | G10: =52/52 -> 1
A11: 300 | B11: =AVERAGE(C11:G11) -> 1 | C11: =52/52 -> 1 | D11: =52/52 -> 1 | E11: =52/52 -> 1 | F11: =52/52 -> 1 | G11: =52/52 -> 1
A12: 330 | B12: =AVERAGE(C12:G12) -> 1 | C12: =52/52 -> 1 | D12: =52/52 -> 1 | E12: =52/52 -> 1 | F12: =52/52 -> 1 | G12: =52/52 -> 1
A13: 360 | B13: =AVERAGE(C13:G13) -> 1 | C13: =52/52 -> 1 | D13: =52/52 -> 1 | E13: =52/52 -> 1 | F13: =52/52 -> 1 | G13: =52/52 -> 1
A14: 390 | B14: =AVERAGE(C14:G14) -> 1 | C14: =52/52 -> 1 | D14: =52/52 -> 1 | E14: =52/52 -> 1 | F14: =52/52 -> 1 | G14: =52/52 -> 1
A15: 420 | B15: =AVERAGE(C15:G15) -> 1 | C15: =52/52 -> 1 | D15: =52/52 -> 1 | E15: =52/52 -> 1 | F15: =52/52 -> 1 | G15: =52/52 -> 1
A16: 450 | B16: =AVERAGE(C16:G16) -> 1 | C16: =52/52 -> 1 | D16: =52/52 -> 1 | E16: =52/52 -> 1 | F16: =52/52 -> 1 | G16: =52/52 -> 1
A17: 480 | B17: =AVERAGE(C17:G17) -> 1 | C17: =52/52 -> 1 | D17: =52/52 -> 1 | E17: =52/52 -> 1 | F17: =52/52 -> 1 | G17: =52/52 -> 1
A18: 510 | B18: =AVERAGE(C18:G18) -> 1 | C18: =52/52 -> 1 | D18: =52/52 -> 1 | E18: =52/52 -> 1 | F18: =52/52 -> 1 | G18: =52/52 -> 1
A19: 540 | B19: =AVERAGE(C19:G19) -> 1 | C19: =52/52 -> 1 | D19: =52/52 -> 1 | E19: =52/52 -> 1 | F19: =52/52 -> 1 | G19: =52/52 -> 1
A20: 570 | B20: =AVERAGE(C20:G20) -> 1 | C20: =52/52 -> 1 | D20: =52/52 -> 1 | E20: =52/52 -> 1 | F20: =52/52 -> 1 | G20: =52/52 -> 1
A21: 600 | B21: =AVERAGE(C21:G21) -> 1 | C21: =52/52 -> 1 | D21: =52/52 -> 1 | E21: =52/52 -> 1 | F21: =52/52 -> 1 | G21: =52/52 -> 1

Sheet XRI Examples-Random
A1: Time | B1: Coverage | C1: Run 1 | D1: Run 2 | E1: Run 3 | F1: Run 4 | G1: Run 5 | J1: Trigger | K1: Grab | L1: Total
A2: 30 | B2: =AVERAGE(C2:G2) -> 0.0038461538 | C2: =0/52 -> 0 | D2: =0/52 -> 0 | E2: =0/52 -> 0 | F2: =1/52 -> 0.019230769 | G2: =0/52 -> 0 | I2: Run 1 | J2: 0/8 | K2: 1/44 | L2: 1/52
A3: 60 | B3: =AVERAGE(C3:G3) -> 0.0038461538 | C3: =0/52 -> 0 | D3: =0/52 -> 0 | E3: =0/52 -> 0 | F3: =1/52 -> 0.019230769 | G3: =0/52 -> 0 | I3: Run 2 | J3: 0/8 | K3: 1/44 | L3: 1/52
A4: 90 | B4: =AVERAGE(C4:G4) -> 0.0038461538 | C4: =0/52 -> 0 | D4: =0/52 -> 0 | E4: =0/52 -> 0 | F4: =1/52 -> 0.019230769 | G4: =0/52 -> 0 | I4: Run 3 | J4: 0/8 | K4: 2/44 | L4: 2/52
A5: 120 | B5: =AVERAGE(C5:G5) -> 0.015384615 | C5: =1/52 -> 0.019230769 | D5: =1/52 -> 0.019230769 | E5: =1/52 -> 0.019230769 | F5: =1/52 -> 0.019230769 | G5: =0/52 -> 0 | I5: Run 4 | J5: 0/8 | K5: 1/44 | L5: 1/52
A6: 150 | B6: =AVERAGE(C6:G6) -> 0.015384615 | C6: =1/52 -> 0.019230769 | D6: =1/52 -> 0.019230769 | E6: =1/52 -> 0.019230769 | F6: =1/52 -> 0.019230769 | G6: =0/52 -> 0 | I6: Run 5 | J6: 0/8 | K6: 0/44 | L6: 0/52
A7: 180 | B7: =AVERAGE(C7:G7) -> 0.015384615 | C7: =1/52 -> 0.019230769 | D7: =1/52 -> 0.019230769 | E7: =1/52 -> 0.019230769 | F7: =1/52 -> 0.019230769 | G7: =0/52 -> 0 | I7: Average | J7: 0/8 | K7: 1/44 | L7: 1/52
A8: 210 | B8: =AVERAGE(C8:G8) -> 0.015384615 | C8: =1/52 -> 0.019230769 | D8: =1/52 -> 0.019230769 | E8: =1/52 -> 0.019230769 | F8: =1/52 -> 0.019230769 | G8: =0/52 -> 0
A9: 240 | B9: =AVERAGE(C9:G9) -> 0.015384615 | C9: =1/52 -> 0.019230769 | D9: =1/52 -> 0.019230769 | E9: =1/52 -> 0.019230769 | F9: =1/52 -> 0.019230769 | G9: =0/52 -> 0
A10: 270 | B10: =AVERAGE(C10:G10) -> 0.015384615 | C10: =1/52 -> 0.019230769 | D10: =1/52 -> 0.019230769 | E10: =1/52 -> 0.019230769 | F10: =1/52 -> 0.019230769 | G10: =0/52 -> 0
A11: 300 | B11: =AVERAGE(C11:G11) -> 0.015384615 | C11: =1/52 -> 0.019230769 | D11: =1/52 -> 0.019230769 | E11: =1/52 -> 0.019230769 | F11: =1/52 -> 0.019230769 | G11: =0/52 -> 0
A12: 330 | B12: =AVERAGE(C12:G12) -> 0.015384615 | C12: =1/52 -> 0.019230769 | D12: =1/52 -> 0.019230769 | E12: =1/52 -> 0.019230769 | F12: =1/52 -> 0.019230769 | G12: =0/52 -> 0
A13: 360 | B13: =AVERAGE(C13:G13) -> 0.015384615 | C13: =1/52 -> 0.019230769 | D13: =1/52 -> 0.019230769 | E13: =1/52 -> 0.019230769 | F13: =1/52 -> 0.019230769 | G13: =0/52 -> 0
A14: 390 | B14: =AVERAGE(C14:G14) -> 0.015384615 | C14: =1/52 -> 0.019230769 | D14: =1/52 -> 0.019230769 | E14: =1/52 -> 0.019230769 | F14: =1/52 -> 0.019230769 | G14: =0/52 -> 0
A15: 420 | B15: =AVERAGE(C15:G15) -> 0.015384615 | C15: =1/52 -> 0.019230769 | D15: =1/52 -> 0.019230769 | E15: =1/52 -> 0.019230769 | F15: =1/52 -> 0.019230769 | G15: =0/52 -> 0
A16: 450 | B16: =AVERAGE(C16:G16) -> 0.019230769 | C16: =1/52 -> 0.019230769 | D16: =1/52 -> 0.019230769 | E16: =2/52 -> 0.038461538 | F16: =1/52 -> 0.019230769 | G16: =0/52 -> 0
A17: 480 | B17: =AVERAGE(C17:G17) -> 0.019230769 | C17: =1/52 -> 0.019230769 | D17: =1/52 -> 0.019230769 | E17: =2/52 -> 0.038461538 | F17: =1/52 -> 0.019230769 | G17: =0/52 -> 0
A18: 510 | B18: =AVERAGE(C18:G18) -> 0.019230769 | C18: =1/52 -> 0.019230769 | D18: =1/52 -> 0.019230769 | E18: =2/52 -> 0.038461538 | F18: =1/52 -> 0.019230769 | G18: =0/52 -> 0
A19: 540 | B19: =AVERAGE(C19:G19) -> 0.019230769 | C19: =1/52 -> 0.019230769 | D19: =1/52 -> 0.019230769 | E19: =2/52 -> 0.038461538 | F19: =1/52 -> 0.019230769 | G19: =0/52 -> 0
A20: 570 | B20: =AVERAGE(C20:G20) -> 0.019230769 | C20: =1/52 -> 0.019230769 | D20: =1/52 -> 0.019230769 | E20: =2/52 -> 0.038461538 | F20: =1/52 -> 0.019230769 | G20: =0/52 -> 0
A21: 600 | B21: =AVERAGE(C21:G21) -> 0.019230769 | C21: =1/52 -> 0.019230769 | D21: =1/52 -> 0.019230769 | E21: =2/52 -> 0.038461538 | F21: =1/52 -> 0.019230769 | G21: =0/52 -> 0

Sheet XRToolKitEssentials-XRintTest
A1: Time | B1: Coverage | C1: Run 1 | D1: Run 2 | E1: Run 3 | F1: Run 4 | G1: Run 5 | J1: Trigger | K1: Grab | L1: Socket | M1: Total | N1: Time
A2: 30 | B2: =AVERAGE(C2:G2) -> 0.8 | C2: =8/10 -> 0.8 | D2: =8/10 -> 0.8 | E2: =8/10 -> 0.8 | F2: =8/10 -> 0.8 | G2: =8/10 -> 0.8 | I2: Run 1 | J2: N/A | K2: 5/5 | L2: 5/5 | M2: 10/10 | N2: 40.77
A3: 60 | B3: =AVERAGE(C3:G3) -> 1 | C3: =10/10 -> 1 | D3: =10/10 -> 1 | E3: =10/10 -> 1 | F3: =10/10 -> 1 | G3: =10/10 -> 1 | I3: Run 2 | J3: N/A | K3: 5/5 | L3: 5/5 | M3: 10/10 | N3: 40.5
A4: 90 | B4: =AVERAGE(C4:G4) -> 1 | C4: =10/10 -> 1 | D4: =10/10 -> 1 | E4: =10/10 -> 1 | F4: =10/10 -> 1 | G4: =10/10 -> 1 | I4: Run 3 | J4: N/A | K4: 5/5 | L4: 5/5 | M4: 10/10 | N4: 40.71
A5: 120 | B5: =AVERAGE(C5:G5) -> 1 | C5: =10/10 -> 1 | D5: =10/10 -> 1 | E5: =10/10 -> 1 | F5: =10/10 -> 1 | G5: =10/10 -> 1 | I5: Run 4 | J5: N/A | K5: 5/5 | L5: 5/5 | M5: 10/10 | N5: 40.58
A6: 150 | B6: =AVERAGE(C6:G6) -> 1 | C6: =10/10 -> 1 | D6: =10/10 -> 1 | E6: =10/10 -> 1 | F6: =10/10 -> 1 | G6: =10/10 -> 1 | I6: Run 5 | J6: N/A | K6: 5/5 | L6: 5/5 | M6: 10/10 | N6: 40.22
A7: 180 | B7: =AVERAGE(C7:G7) -> 1 | C7: =10/10 -> 1 | D7: =10/10 -> 1 | E7: =10/10 -> 1 | F7: =10/10 -> 1 | G7: =10/10 -> 1 | I7: Average | J7: N/A | K7: 5/5 | L7: 5/5 | M7: 10/10 | N7: =AVERAGE(N2:N6) -> 40.556
A8: 210 | B8: =AVERAGE(C8:G8) -> 1 | C8: =10/10 -> 1 | D8: =10/10 -> 1 | E8: =10/10 -> 1 | F8: =10/10 -> 1 | G8: =10/10 -> 1
A9: 240 | B9: =AVERAGE(C9:G9) -> 1 | C9: =10/10 -> 1 | D9: =10/10 -> 1 | E9: =10/10 -> 1 | F9: =10/10 -> 1 | G9: =10/10 -> 1
A10: 270 | B10: =AVERAGE(C10:G10) -> 1 | C10: =10/10 -> 1 | D10: =10/10 -> 1 | E10: =10/10 -> 1 | F10: =10/10 -> 1 | G10: =10/10 -> 1
A11: 300 | B11: =AVERAGE(C11:G11) -> 1 | C11: =10/10 -> 1 | D11: =10/10 -> 1 | E11: =10/10 -> 1 | F11: =10/10 -> 1 | G11: =10/10 -> 1
A12: 330 | B12: =AVERAGE(C12:G12) -> 1 | C12: =10/10 -> 1 | D12: =10/10 -> 1 | E12: =10/10 -> 1 | F12: =10/10 -> 1 | G12: =10/10 -> 1
A13: 360 | B13: =AVERAGE(C13:G13) -> 1 | C13: =10/10 -> 1 | D13: =10/10 -> 1 | E13: =10/10 -> 1 | F13: =10/10 -> 1 | G13: =10/10 -> 1
A14: 390 | B14: =AVERAGE(C14:G14) -> 1 | C14: =10/10 -> 1 | D14: =10/10 -> 1 | E14: =10/10 -> 1 | F14: =10/10 -> 1 | G14: =10/10 -> 1
A15: 420 | B15: =AVERAGE(C15:G15) -> 1 | C15: =10/10 -> 1 | D15: =10/10 -> 1 | E15: =10/10 -> 1 | F15: =10/10 -> 1 | G15: =10/10 -> 1
A16: 450 | B16: =AVERAGE(C16:G16) -> 1 | C16: =10/10 -> 1 | D16: =10/10 -> 1 | E16: =10/10 -> 1 | F16: =10/10 -> 1 | G16: =10/10 -> 1
A17: 480 | B17: =AVERAGE(C17:G17) -> 1 | C17: =10/10 -> 1 | D17: =10/10 -> 1 | E17: =10/10 -> 1 | F17: =10/10 -> 1 | G17: =10/10 -> 1
A18: 510 | B18: =AVERAGE(C18:G18) -> 1 | C18: =10/10 -> 1 | D18: =10/10 -> 1 | E18: =10/10 -> 1 | F18: =10/10 -> 1 | G18: =10/10 -> 1
A19: 540 | B19: =AVERAGE(C19:G19) -> 1 | C19: =10/10 -> 1 | D19: =10/10 -> 1 | E19: =10/10 -> 1 | F19: =10/10 -> 1 | G19: =10/10 -> 1
... A21: 600 | B21: =AVERAGE(C21:G21) -> 1 | C21: =10/10 -> 1 | D21: =10/10 -> 1 | E21: =10/10 -> 1 | F21: =10/10 -> 1 | G21: =10/10 -> 1

Sheet XRToolKitEssentials-Random
A1: Time | B1: Coverage | C1: Run 1 | D1: Run 2 | E1: Run 3 | F1: Run 4 | G1: Run 5 | J1: Trigger | K1: Grab | L1: Socket | M1: Total
A2: 30 | B2: =AVERAGE(C2:G2) -> 0 | C2: =0/10 -> 0 | D2: =0/10 -> 0 | E2: =0/10 -> 0 | F2: =0/10 -> 0 | G2: =0/10 -> 0 | I2: Run 1 | J2: N/A | K2: 3/5 | L2: 0/5 | M2: 3/10
A3: 60 | B3: =AVERAGE(C3:G3) -> 0.02 | C3: =0/10 -> 0 | D3: =0/10 -> 0 | E3: =1/10 -> 0.1 | F3: =0/10 -> 0 | G3: =0/10 -> 0 | I3: Run 2 | J3: N/A | K3: 1/5 | L3: 0/5 | M3: 1/10
A4: 90 | B4: =AVERAGE(C4:G4) -> 0.04 | C4: =0/10 -> 0 | D4: =0/10 -> 0 | E4: =1/10 -> 0.1 | F4: =1/10 -> 0.1 | G4: =0/10 -> 0 | I4: Run 3 | J4: N/A | K4: 1/5 | L4: 0/5 | M4: 1/10
A5: 120 | B5: =AVERAGE(C5:G5) -> 0.04 | C5: =0/10 -> 0 | D5: =0/10 -> 0 | E5: =1/10 -> 0.1 | F5: =1/10 -> 0.1 | G5: =0/10 -> 0 | I5: Run 4 | J5: N/A | K5: 3/5 | L5: 0/5 | M5: 3/10
A6: 150 | B6: =AVERAGE(C6:G6) -> 0.04 | C6: =0/10 -> 0 | D6: =0/10 -> 0 | E6: =1/10 -> 0.1 | F6: =1/10 -> 0.1 | G6: =0/10 -> 0 | I6: Run 5 | J6: N/A | K6: 2/5 | L6: 0/5 | M6: 2/10
A7: 180 | B7: =AVERAGE(C7:G7) -> 0.06 | C7: =0/10 -> 0 | D7: =0/10 -> 0 | E7: =1/10 -> 0.1 | F7: =2/10 -> 0.2 | G7: =0/10 -> 0 | I7: Average | J7: N/A | K7: 2/5 | L7: 0/5 | M7: 2/10
A8: 210 | B8: =AVERAGE(C8:G8) -> 0.06 | C8: =0/10 -> 0 | D8: =0/10 -> 0 | E8: =1/10 -> 0.1 | F8: =2/10 -> 0.2 | G8: =0/10 -> 0
A9: 240 | B9: =AVERAGE(C9:G9) -> 0.1 | C9: =1/10 -> 0.1 | D9: =0/10 -> 0 | E9: =1/10 -> 0.1 | F9: =3/10 -> 0.3 | G9: =0/10 -> 0
A10: 270 | B10: =AVERAGE(C10:G10) -> 0.12 | C10: =1/10 -> 0.1 | D10: =1/10 -> 0.1 | E10: =1/10 -> 0.1 | F10: =3/10 -> 0.3 | G10: =0/10 -> 0
A11: 300 | B11: =AVERAGE(C11:G11) -> 0.12 | C11: =1/10 -> 0.1 | D11: =1/10 -> 0.1 | E11: =1/10 -> 0.1 | F11: =3/10 -> 0.3 | G11: =0/10 -> 0
A12: 330 | B12: =AVERAGE(C12:G12) -> 0.12 | C12: =1/10 -> 0.1 | D12: =1/10 -> 0.1 | E12: =1/10 -> 0.1 | F12: =3/10 -> 0.3 | G12: =0/10 -> 0
A13: 360 | B13: =AVERAGE(C13:G13) -> 0.12 | C13: =1/10 -> 0.1 | D13: =1/10 -> 0.1 | E13: =1/10 -> 0.1 | F13: =3/10 -> 0.3 | G13: =0/10 -> 0
A14: 390 | B14: =AVERAGE(C14:G14) -> 0.12 | C14: =1/10 -> 0.1 | D14: =1/10 -> 0.1 | E14: =1/10 -> 0.1 | F14: =3/10 -> 0.3 | G14: =0/10 -> 0
A15: 420 | B15: =AVERAGE(C15:G15) -> 0.12 | C15: =1/10 -> 0.1 | D15: =1/10 -> 0.1 | E15: =1/10 -> 0.1 | F15: =3/10 -> 0.3 | G15: =0/10 -> 0
A16: 450 | B16: =AVERAGE(C16:G16) -> 0.16 | C16: =3/10 -> 0.3 | D16: =1/10 -> 0.1 | E16: =1/10 -> 0.1 | F16: =3/10 -> 0.3 | G16: =0/10 -> 0
A17: 480 | B17: =AVERAGE(C17:G17) -> 0.16 | C17: =3/10 -> 0.3 | D17: =1/10 -> 0.1 | E17: =1/10 -> 0.1 | F17: =3/10 -> 0.3 | G17: =0/10 -> 0
A18: 510 | B18: =AVERAGE(C18:G18) -> 0.16 | C18: =3/10 -> 0.3 | D18: =1/10 -> 0.1 | E18: =1/10 -> 0.1 | F18: =3/10 -> 0.3 | G18: =0/10 -> 0
A19: 540 | B19: =AVERAGE(C19:G19) -> 0.16 | C19: =3/10 -> 0.3 | D19: =1/10 -> 0.1 | E19: =1/10 -> 0.1 | F19: =3/10 -> 0.3 | G19: =0/10 -> 0
A20: 570 | B20: =AVERAGE(C20:G20) -> 0.18 | C20: =3/10 -> 0.3 | D20: =1/10 -> 0.1 | E20: =1/10 -> 0.1 | F20: =3/10 -> 0.3 | G20: =1/10 -> 0.1
A21: 600 | B21: =AVERAGE(C21:G21) -> 0.2 | C21: =3/10 -> 0.3 | D21: =1/10 -> 0.1 | E21: =1/10 -> 0.1 | F21: =3/10 -> 0.3 | G21: =2/10 -> 0.2

Sheet VR-Room-XRintTest
A1: Time | B1: Coverage | C1: Run 1 | D1: Run 2 | E1: Run 3 | F1: Run 4 | G1: Run 5 | J1: Trigger | K1: Grab | L1: Socket | M1: Total
A2: 30 | B2: =AVERAGE(C2:G2) -> 0.1 | C2: =4/60 -> 0.066666667 | D2: =6/60 -> 0.1 | E2: =6/60 -> 0.1 | F2: =8/60 -> 0.13333333 | G2: =6/60 -> 0.1 | I2: Run 1 | J2: 6/6 | K2: 20/22 | L2: 24/32 | M2: 50/60
A3: 60 | B3: =AVERAGE(C3:G3) -> 0.17333333 | C3: =9/60 -> 0.15 | D3: =10/60 -> 0.16666667 | E3: =10/60 -> 0.16666667 | F3: =11/60 -> 0.18333333 | G3: =12/60 -> 0.2 | I3: Run 2 | J3: 6/6 | K3: 20/22 | L3: 24/32 | M3: 50/60
A4: 90 | B4: =AVERAGE(C4:G4) -> 0.26 | C4: =13/60 -> 0.21666667 | D4: =17/60 -> 0.28333333 | E4: =17/60 -> 0.28333333 | F4: =17/60 -> 0.28333333 | G4: =14/60 -> 0.23333333 | I4: Run 3 | J4: 6/6 | K4: 20/22 | L4: 24/32 | M4: 50/60
